Workbook

Sheet Sheet1
A1: # | B1: 用户 | C1: 电子邮件 | D1: 学校 | E1: 名称 | F1: 学号 | G1: 总分数 | H1: #1 信号连接 | I1: #2 谜题 | J1: #3 最古老的传说
A2: 1 | B2: A036 | C2: A036@qq.com | D2: 佛山市南海区石门中学 | E2: 王梓睿 | G2: 266 | H2: 100 | I2: 66 | J2: 100
A3: 2 | B3: A015 | C3: A015@qq.com | D3: 华南师范大学附属中学 | E3: 叶名瀚 | G3: 234 | H3: 100 | I3: 100 | J3: 34
A4: 3 | B4: B015 | C4: B015@qq.com | D4: 杭州市第二中学 | E4: 郑乐章 | G4: 225 | H4: 100 | I4: 100 | J4: 25
A5: 3 | B5: A022 | C5: A022@qq.com | D5: 重庆市巴蜀中学校 | E5: 李知检 | G5: 225 | H5: 100 | I5: 100 | J5: 25
A6: 3 | B6: B007 | C6: B007@qq.com | D6: 北京大学附属中学 | E6: 陈一苇 | G6: 225 | H6: 100 | I6: 100 | J6: 25
A7: 3 | B7: A026 | C7: A026@qq.com | D7: 杭州市第二中学 | E7: 郭音赫 | G7: 225 | H7: 100 | I7: 100 | J7: 25
A8: 3 | B8: A001 | C8: A001@qq.com | D8: 华南师范大学附属中学 | E8: 戴睿宸 | G8: 225 | H8: 100 | I8: 100 | J8: 25
A9: 3 | B9: A004 | C9: A004@qq.com | D9: 华南师范大学附属中学 | E9: 叶隽霖 | G9: 225 | H9: 100 | I9: 100 | J9: 25
A10: 9 | B10: A043 | C10: A043@qq.com | D10: 唐山市第一中学 | E10: 范小冉 | G10: 218 | H10: 100 | I10: 100 | J10: 18
A11: 9 | B11: A002 | C11: A002@qq.com | D11: 重庆市巴蜀中学校 | E11: 殷骏 | G11: 218 | H11: 100 | I11: 100 | J11: 18
A12: 11 | B12: A025 | C12: A025@qq.com | D12: 长郡中学 | E12: 程楷轩 | G12: 207 | H12: 100 | I12: 100 | J12: 7
A13: 11 | B13: B005 | C13: B005@qq.com | D13: 西南大学附属中学校 | E13: 刘恒卓 | G13: 207 | H13: 100 | I13: 100 | J13: 7
... A62: 58 | B62: C015 | C62: C015@qq.com | D62: 安徽师范大学附属中学 | E62: 赵旭初 | G62: 107 | H62: 100 | I62: 0 | J62: 7
A63: 58 | B63: D004 | C63: D004@qq.com | E63: 关永丞 | G63: 107 | H63: 100 | I63: 0 | J63: 7
A64: 58 | B64: B002 | C64: B002@qq.com | D64: 成都市锦江区嘉祥外国语高级中学 | E64: 王译萱 | G64: 107 | H64: 100 | I64: 0 | J64: 7
A65: 58 | B65: D033 | C65: D033@qq.com | D65: 杭州市第二中学 | E65: 陈元熙 | G65: 107 | H65: 100 | I65: 0 | J65: 7
A66: 65 | B66: D026 | C66: D026@qq.com | D66: 杭州市第二中学 | E66: 斯嘉智 | G66: 100 | H66: 100 | I66: 0 | J66: 0
A67: 65 | B67: D018 | C67: D018@qq.com | D67: 中山市三鑫学校 | E67: 严启晋 | G67: 100 | H67: 100 | I67: 0 | J67: 0
A68: 65 | B68: B032 | C68: B032@qq.com | D68: 成都市第七中学 | E68: 古皓羽 | G68: 100 | H68: 100 | I68: 0 | J68: 0
A69: 65 | B69: B038 | C69: B038@qq.com | D69: 广东实验中学 | E69: 苏昱霖 | G69: 100 | H69: 100 | I69: 0 | J69: 0
A70: 65 | B70: B025 | C70: B025@qq.com | D70: 中山市中山纪念中学 | E70: 邓承羽 | G70: 100 | H70: 100 | I70: 0 | J70: 0
A71: 65 | B71: B034 | C71: B034@qq.com | D71: 广东实验中学 | E71: 宋承璋 | G71: 100 | H71: 100 | I71: 0 | J71: 0
A72: 65 | B72: A028 | C72: A028@qq.com | D72: 重庆市第八中学校 | E72: 彭彦桐 | F72: A028 | G72: 100 | H72: 100 | I72: 0 | J72: 0
A73: 65 | B73: B011 | C73: B011@qq.com | D73: 西安市铁一中学 | E73: 李倏嘉 | G73: 100 | H73: 100 | I73: 0 | J73: 0
A74: 65 | B74: A039 | C74: A039@qq.com | D74: 北京市十一学校 | E74: 方铨铎 | G74: 100 | H74: 100 | I74: 0 | J74: 0
A75: 65 | B75: B027 | C75: B027@qq.com | D75: 长沙市第一中学 | E75: 匡宸锐 | G75: 100 | H75: 100 | I75: 0 | J75: 0
A76: 65 | B76: D038 | C76: D038@qq.com | D76: 中山市中山纪念中学 | E76: 邓致远 | G76: 100 | H76: 100 | I76: 0 | J76: 0
A77: 65 | B77: C034 | C77: C034@qq.com | D77: 广州大学附属中学 | E77: 赵稻道 | G77: 100 | H77: 100 | I77: 0 | J77: 0
A78: 65 | B78: teacher | C78: teacher@qq.com | E78: teacher | G78: 100 | H78: 0 | I78: 0 | J78: 100
A79: 78 | B79: B029 | C79: B029@qq.com | D79: 浙江省诸暨市海亮高级中学 | E79: 姚岩峰 | G79: 90 | H79: 24 | I79: 66 | J79: 0
A80: 79 | B80: C008 | C80: C008@qq.com | D80: 浙江省诸暨市海亮高级中学 | E80: 边逸城 | G80: 82 | H80: 33 | I80: 42 | J80: 7
A81: 80 | B81: C013 | C81: C013@qq.com | D81: 清华大学附属中学 | E81: 黄思源 | G81: 75 | H81: 68 | I81: 0 | J81: 7
A82: 81 | B82: B001 | C82: B001@qq.com | D82: 上海市曹杨第二中学 | E82: 李烨霖 | G82: 66 | H82: 24 | I82: 42 | J82: 0
A83: 81 | B83: D030 | C83: D030@qq.com | D83: 中山市中山纪念中学 | E83: 黄羿信 | G83: 66 | H83: 59 | I83: 0 | J83: 7
A84: 83 | B84: A011 | C84: A011@qq.com | D84: 广州大学附属中学 | E84: 张乐涛 | G84: 60 | H84: 42 | I84: 0 | J84: 18
A85: 84 | B85: A018 | C85: A018@qq.com | D85: 中山市三鑫学校 | E85: 袁煜智 | G85: 58 | H85: 42 | I85: 0 | J85: 16
A86: 84 | B86: D009 | C86: D009@qq.com | D86: 中山市中山纪念中学 | E86: 彭炜翔 | G86: 58 | H86: 42 | I86: 0 | J86: 16
A87: 86 | B87: C002 | C87: C002@qq.com | D87: 深圳市耀华实验学校 | E87: 刘航聿 | G87: 51 | H87: 24 | I87: 27 | J87: 0
A88: 86 | B88: D021 | C88: D021@qq.com | D88: 广东省汕头市金山中学 | E88: 杨其臻 | G88: 51 | H88: 24 | I88: 27 | J88: 0
...

Sheet Sheet2
A1: # | B1: 用户 | C1: 电子邮件 | D1: 学校 | E1: 名称 | F1: 学号 | G1: 总分数 | H1: #1 猪染色(color) | I1: #2 猪相遇(meet) | J1: #3 猪画画(draw)
A2: 1 | B2: A011 | C2: A011@qq.com | D2: 广州大学附属中学 | E2: 张乐涛 | G2: 234 | H2: 100 | I2: 100 | J2: 34
A3: 2 | B3: A036 | C3: A036@qq.com | D3: 佛山市南海区石门中学 | E3: 王梓睿 | G3: 233 | H3: 100 | I3: 100 | J3: 33
A4: 3 | B4: A004 | C4: A004@qq.com | D4: 华南师范大学附属中学 | E4: 叶隽霖 | G4: 225 | H4: 100 | I4: 100 | J4: 25
A5: 4 | B5: A026 | C5: A026@qq.com | D5: 杭州市第二中学 | E5: 郭音赫 | G5: 215 | H5: 100 | I5: 100 | J5: 15
A6: 5 | B6: A038 | C6: A038@qq.com | D6: 广州大学附属中学 | E6: 黄豆 | G6: 214 | H6: 100 | I6: 56 | J6: 58
A7: 6 | B7: B010 | C7: B010@qq.com | D7: 长郡中学 | E7: 陈泓睿 | G7: 212 | H7: 100 | I7: 100 | J7: 12
A8: 7 | B8: A014 | C8: A014@qq.com | D8: 上海外国语大学附属外国语学校 | E8: 吴思成 | G8: 201 | H8: 100 | I8: 76 | J8: 25
A9: 7 | B9: A007 | C9: A007@qq.com | D9: 上海市曹杨第二中学 | E9: 王翊临 | G9: 201 | H9: 100 | I9: 76 | J9: 25
A10: 9 | B10: B041 | C10: B041@qq.com | D10: 福建省厦门第一中学 | E10: 张子朴 | G10: 200 | H10: 100 | I10: 0 | J10: 100
A11: 10 | B11: A021 | C11: A021@qq.com | D11: 深圳中学 | E11: 李子优 | G11: 197 | H11: 100 | I11: 76 | J11: 21
A12: 11 | B12: A025 | C12: A025@qq.com | D12: 长郡中学 | E12: 程楷轩 | G12: 190 | H12: 100 | I12: 56 | J12: 34
A13: 11 | B13: A010 | C13: A010@qq.com | D13: 浙江省诸暨市海亮高级中学 | E13: 吴旻逸 | G13: 190 | H13: 100 | I13: 56 | J13: 34
... A37: 29 | B37: A039 | C37: A039@qq.com | D37: 北京市十一学校 | E37: 方铨铎 | G37: 168 | H37: 100 | I37: 56 | J37: 12
A38: 29 | B38: A028 | C38: A028@qq.com | D38: 重庆市第八中学校 | E38: 彭彦桐 | F38: A028 | G38: 168 | H38: 100 | I38: 56 | J38: 12
A39: 29 | B39: C028 | C39: C028@qq.com | D39: 广州大学附属中学 | E39: 陈瀚熹 | G39: 168 | H39: 100 | I39: 44 | J39: 24
A40: 29 | B40: A019 | C40: A019@qq.com | D40: 长郡中学 | E40: 周雨衡 | G40: 168 | H40: 100 | I40: 56 | J40: 12
A41: 40 | B41: C013 | C41: C013@qq.com | D41: 清华大学附属中学 | E41: 黄思源 | G41: 166 | H41: 100 | I41: 32 | J41: 34
A42: 40 | B42: C008 | C42: C008@qq.com | D42: 浙江省诸暨市海亮高级中学 | E42: 边逸城 | G42: 166 | H42: 100 | I42: 32 | J42: 34
A43: 40 | B43: A018 | C43: A018@qq.com | D43: 中山市三鑫学校 | E43: 袁煜智 | G43: 166 | H43: 100 | I43: 32 | J43: 34
A44: 43 | B44: C033 | C44: C033@qq.com | D44: 深圳北理莫斯科大学附属实验中学 | E44: 李泽鸿 | G44: 165 | H44: 100 | I44: 44 | J44: 21
A45: 44 | B45: D031 | C45: D031@qq.com | D45: 北京大学附属中学 | E45: 王心卓 | G45: 163 | H45: 100 | I45: 32 | J45: 31
A46: 45 | B46: B025 | C46: B025@qq.com | D46: 中山市中山纪念中学 | E46: 邓承羽 | G46: 157 | H46: 100 | I46: 32 | J46: 25
A47: 45 | B47: B008 | C47: B008@qq.com | D47: 北京大学附属中学 | E47: 许远正 | G47: 157 | H47: 100 | I47: 32 | J47: 25
A48: 45 | B48: C001 | C48: C001@qq.com | D48: 佛山市南海区石门中学 | E48: 赵崧维 | G48: 157 | H48: 100 | I48: 32 | J48: 25
A49: 45 | B49: B015 | C49: B015@qq.com | D49: 杭州市第二中学 | E49: 郑乐章 | G49: 157 | H49: 100 | I49: 32 | J49: 25
A50: 45 | B50: B002 | C50: B002@qq.com | D50: 成都市锦江区嘉祥外国语高级中学 | E50: 王译萱 | G50: 157 | H50: 100 | I50: 32 | J50: 25
... A116: 111 | B116: D016 | C116: D016@qq.com | D116: 中山市石岐中学 | E116: 严谨 | G116: 112 | H116: 100 | I116: 0 | J116: 12
A117: 111 | B117: D004 | C117: D004@qq.com | E117: 关永丞 | G117: 112 | H117: 100 | I117: 0 | J117: 12
A118: 111 | B118: D029 | C118: D029@qq.com | D118: 中山市中山纪念中学 | E118: 蔡大为 | G118: 112 | H118: 100 | I118: 0 | J118: 12
A119: 111 | B119: B043 | C119: B043@qq.com | D119: 长郡中学 | E119: 易牧华 | G119: 112 | H119: 100 | I119: 0 | J119: 12
A120: 119 | B120: C010 | C120: C010@qq.com | D120: 广州大学附属中学 | E120: 梁博文 | G120: 103 | H120: 35 | I120: 56 | J120: 12
A121: 120 | B121: C012 | C121: C012@qq.com | D121: 长沙市第一中学 | E121: 王奕博 | G121: 102 | H121: 70 | I121: 20 | J121: 12
A122: 121 | B122: A042 | C122: A042@qq.com | D122: 华南师范大学附属中学 | E122: 吕林熹 | G122: 100 | H122: 100 | I122: 0 | J122: 0
A123: 121 | B123: C029 | C123: C029@qq.com | D123: 深圳市高级中学 | E123: 梁意森 | G123: 100 | H123: 100 | I123: 0 | J123: 0
A124: 121 | B124: D033 | C124: D033@qq.com | D124: 杭州市第二中学 | E124: 陈元熙 | G124: 100 | H124: 100 | I124: 0 | J124: 0
A125: 121 | B125: C042 | C125: C042@qq.com | D125: 陕西渭南高新中学 | E125: 张嘉宁 | G125: 100 | H125: 100 | I125: 0 | J125: 0
A126: 121 | B126: B011 | C126: B011@qq.com | D126: 西安市铁一中学 | E126: 李倏嘉 | G126: 100 | H126: 100 | I126: 0 | J126: 0
A127: 121 | B127: A003 | C127: A003@qq.com | D127: 江苏省锡山高级中学 | E127: 陶奕潇 | G127: 100 | H127: 100 | I127: 0 | J127: 0
A128: 121 | B128: D025 | C128: D025@qq.com | D128: 北京大学附属中学 | E128: 黄子怀 | G128: 100 | H128: 100 | I128: 0 | J128: 0
...

Sheet Sheet3
A1: # | B1: 用户 | C1: 电子邮件 | D1: 学校 | E1: 名称 | F1: 学号 | G1: 总分数 | H1: #1 双飞燕 | I1: #2 裹锋 | J1: #3 气合
A2: 1 | B2: A023 | C2: A023@qq.com | D2: 浙江省诸暨市海亮高级中学 | E2: 刘家萌 | G2: 300 | H2: 100 | I2: 100 | J2: 100
A3: 1 | B3: A014 | C3: A014@qq.com | D3: 上海外国语大学附属外国语学校 | E3: 吴思成 | G3: 300 | H3: 100 | I3: 100 | J3: 100
A4: 1 | B4: A002 | C4: A002@qq.com | D4: 重庆市巴蜀中学校 | E4: 殷骏 | G4: 300 | H4: 100 | I4: 100 | J4: 100
A5: 4 | B5: B005 | C5: B005@qq.com | D5: 西南大学附属中学校 | E5: 刘恒卓 | G5: 280 | H5: 100 | I5: 100 | J5: 80
A6: 5 | B6: A004 | C6: A004@qq.com | D6: 华南师范大学附属中学 | E6: 叶隽霖 | G6: 270 | H6: 100 | I6: 100 | J6: 70
A7: 5 | B7: A036 | C7: A036@qq.com | D7: 佛山市南海区石门中学 | E7: 王梓睿 | G7: 270 | H7: 100 | I7: 100 | J7: 70
A8: 7 | B8: A031 | C8: A031@qq.com | D8: 华中师范大学第一附属中学 | E8: 伍敬宇 | G8: 260 | H8: 100 | I8: 100 | J8: 60
A9: 7 | B9: A011 | C9: A011@qq.com | D9: 广州大学附属中学 | E9: 张乐涛 | G9: 260 | H9: 100 | I9: 60 | J9: 100
A10: 7 | B10: C004 | C10: C004@qq.com | D10: 安徽师范大学附属中学 | E10: 张宗岳 | G10: 260 | H10: 100 | I10: 60 | J10: 100
A11: 7 | B11: D026 | C11: D026@qq.com | D11: 杭州市第二中学 | E11: 斯嘉智 | G11: 260 | H11: 100 | I11: 100 | J11: 60
A12: 11 | B12: A021 | C12: A021@qq.com | D12: 深圳中学 | E12: 李子优 | G12: 250 | H12: 100 | I12: 100 | J12: 50
A13: 11 | B13: B001 | C13: B001@qq.com | D13: 上海市曹杨第二中学 | E13: 李烨霖 | G13: 250 | H13: 100 | I13: 100 | J13: 50
... A23: 21 | B23: A013 | C23: A013@qq.com | D23: 中山市中山纪念中学 | E23: 胡金勇 | G23: 240 | H23: 100 | I23: 100 | J23: 40
A24: 21 | B24: A028 | C24: A028@qq.com | D24: 重庆市第八中学校 | E24: 彭彦桐 | F24: A028 | G24: 240 | H24: 100 | I24: 100 | J24: 40
A25: 21 | B25: D034 | C25: D034@qq.com | D25: 长沙市中雅培粹学校 | E25: 李学睿 | G25: 240 | H25: 100 | I25: 100 | J25: 40
A26: 21 | B26: A033 | C26: A033@qq.com | D26: 广州市铁一中学 | E26: 于镓赫 | G26: 240 | H26: 100 | I26: 100 | J26: 40
A27: 21 | B27: A017 | C27: A017@qq.com | D27: 深圳中学 | E27: 朱瀚阳 | G27: 240 | H27: 100 | I27: 100 | J27: 40
A28: 21 | B28: B038 | C28: B038@qq.com | D28: 广东实验中学 | E28: 苏昱霖 | G28: 240 | H28: 100 | I28: 100 | J28: 40
A29: 21 | B29: B008 | C29: B008@qq.com | D29: 北京大学附属中学 | E29: 许远正 | G29: 240 | H29: 100 | I29: 100 | J29: 40
A30: 21 | B30: A024 | C30: A024@qq.com | D30: 佛山市南海区石门中学 | E30: 谢朝阳 | G30: 240 | H30: 100 | I30: 100 | J30: 40
A31: 21 | B31: C041 | C31: C041@qq.com | D31: 成都市第七中学 | E31: 蒋林逍 | G31: 240 | H31: 100 | I31: 100 | J31: 40
A32: 21 | B32: A015 | C32: A015@qq.com | D32: 华南师范大学附属中学 | E32: 叶名瀚 | G32: 240 | H32: 100 | I32: 100 | J32: 40
A33: 21 | B33: A020 | C33: A020@qq.com | D33: 深圳外国语学校 | E33: 许由 | G33: 240 | H33: 100 | I33: 100 | J33: 40
A34: 21 | B34: A006 | C34: A006@qq.com | D34: 华南师范大学附属中学 | E34: 李承翰 | G34: 240 | H34: 100 | I34: 100 | J34: 40
A35: 21 | B35: A001 | C35: A001@qq.com | D35: 华南师范大学附属中学 | E35: 戴睿宸 | G35: 240 | H35: 100 | I35: 100 | J35: 40
A36: 21 | B36: B043 | C36: B043@qq.com | D36: 长郡中学 | E36: 易牧华 | G36: 240 | H36: 100 | I36: 100 | J36: 40
... A89: 77 | B89: B020 | C89: B020@qq.com | D89: 深圳中学 | E89: 韦锦成 | G89: 180 | H89: 100 | I89: 40 | J89: 40
A90: 77 | B90: D004 | C90: D004@qq.com | E90: 关永丞 | G90: 180 | H90: 100 | I90: 60 | J90: 20
A91: 77 | B91: D040 | C91: D040@qq.com | D91: 长沙市第一中学 | E91: 杨济帆 | G91: 180 | H91: 100 | I91: 40 | J91: 40
A92: 77 | B92: C040 | C92: C040@qq.com | D92: 广州大学附属中学 | E92: 姚宇翔 | G92: 180 | H92: 100 | I92: 40 | J92: 40
A93: 92 | B93: A041 | C93: A041@qq.com | D93: 中山市中山纪念中学 | E93: 周祎 | G93: 179 | H93: 79 | I93: 60 | J93: 40
A94: 93 | B94: D022 | C94: D022@qq.com | D94: 中山市石岐中学 | E94: 钟宇杰 | G94: 177 | H94: 77 | I94: 60 | J94: 40
A95: 94 | B95: B022 | C95: B022@qq.com | D95: 乐山高新区嘉祥外国语学校 | E95: 孙邦博 | G95: 175 | H95: 75 | I95: 60 | J95: 40
A96: 95 | B96: C003 | C96: C003@qq.com | D96: 深圳中学 | E96: 伍佳鑫 | G96: 171 | H96: 51 | I96: 100 | J96: 20
A97: 95 | B97: A040 | C97: A040@qq.com | D97: 广州大学附属中学 | E97: 刘君仪 | G97: 171 | H97: 51 | I97: 80 | J97: 40
A98: 97 | B98: C025 | C98: C025@qq.com | D98: 广州大学附属中学 | E98: 李钧 | G98: 170 | H98: 100 | I98: 40 | J98: 30
A99: 98 | B99: D009 | C99: D009@qq.com | D99: 中山市中山纪念中学 | E99: 彭炜翔 | G99: 169 | H99: 79 | I99: 60 | J99: 30
A100: 99 | B100: B018 | C100: B018@qq.com | D100: 重庆市育才中学校 | E100: 周琛乔 | G100: 168 | H100: 88 | I100: 60 | J100: 20
A101: 100 | B101: B036 | C101: B036@qq.com | D101: 浙江省诸暨市海亮高级中学 | E101: 谢汝瑜 | G101: 164 | H101: 84 | I101: 40 | J101: 40
...

Sheet Sheet4
A1: # | B1: 用户 | C1: 电子邮件 | D1: 学校 | E1: 名称 | F1: 学号 | G1: 总分数 | H1: #1 双生棋子 | I1: #2 死亡路线 | J1: #3 夜空奏
A2: 1 | B2: A023 | C2: A023@qq.com | D2: 浙江省诸暨市海亮高级中学 | E2: 刘家萌 | G2: 300 | H2: 100 | I2: 100 | J2: 100
A3: 1 | B3: A031 | C3: A031@qq.com | D3: 华中师范大学第一附属中学 | E3: 伍敬宇 | G3: 300 | H3: 100 | I3: 100 | J3: 100
A4: 3 | B4: A036 | C4: A036@qq.com | D4: 佛山市南海区石门中学 | E4: 王梓睿 | G4: 295 | H4: 100 | I4: 95 | J4: 100
A5: 4 | B5: B033 | C5: B033@qq.com | D5: 华中师范大学第一附属中学 | E5: 柳子宁 | G5: 280 | H5: 100 | I5: 80 | J5: 100
A6: 5 | B6: A001 | C6: A001@qq.com | D6: 华南师范大学附属中学 | E6: 戴睿宸 | G6: 269 | H6: 100 | I6: 100 | J6: 69
A7: 5 | B7: A038 | C7: A038@qq.com | D7: 广州大学附属中学 | E7: 黄豆 | G7: 269 | H7: 100 | I7: 100 | J7: 69
A8: 7 | B8: A007 | C8: A007@qq.com | D8: 上海市曹杨第二中学 | E8: 王翊临 | G8: 222 | H8: 100 | I8: 100 | J8: 22
A9: 7 | B9: A004 | C9: A004@qq.com | D9: 华南师范大学附属中学 | E9: 叶隽霖 | G9: 222 | H9: 100 | I9: 100 | J9: 22
A10: 7 | B10: B019 | C10: B019@qq.com | D10: 深圳市宝安中学（集团）高中部 | E10: 蒋骏豪 | G10: 222 | H10: 100 | I10: 100 | J10: 22
A11: 7 | B11: A011 | C11: A011@qq.com | D11: 广州大学附属中学 | E11: 张乐涛 | G11: 222 | H11: 100 | I11: 100 | J11: 22
A12: 7 | B12: C004 | C12: C004@qq.com | D12: 安徽师范大学附属中学 | E12: 张宗岳 | G12: 222 | H12: 100 | I12: 100 | J12: 22
A13: 7 | B13: A002 | C13: A002@qq.com | D13: 重庆市巴蜀中学校 | E13: 殷骏 | G13: 222 | H13: 100 | I13: 100 | J13: 22
... A65: 59 | B65: B037 | C65: B037@qq.com | D65: 中山市中山纪念中学 | E65: 黄景梵 | G65: 116 | H65: 100 | I65: 11 | J65: 5
A66: 59 | B66: D004 | C66: D004@qq.com | E66: 关永丞 | G66: 116 | H66: 100 | I66: 11 | J66: 5
A67: 66 | B67: B018 | C67: B018@qq.com | D67: 重庆市育才中学校 | E67: 周琛乔 | G67: 115 | H67: 100 | I67: 10 | J67: 5
A68: 67 | B68: D020 | C68: D020@qq.com | D68: 佛山市南海区狮山镇英才学校 | E68: 宁浩天 | G68: 112 | H68: 100 | I68: 11 | J68: 1
A69: 67 | B69: C001 | C69: C001@qq.com | D69: 佛山市南海区石门中学 | E69: 赵崧维 | G69: 112 | H69: 100 | I69: 0 | J69: 12
A70: 67 | B70: A009 | C70: A009@qq.com | D70: 成都外国语学校 | E70: 蒋明睿 | G70: 112 | H70: 100 | I70: 12 | J70: 0
A71: 67 | B71: B030 | C71: B030@qq.com | D71: 成都外国语学校 | E71: 马周 | G71: 112 | H71: 100 | I71: 11 | J71: 1
A72: 67 | B72: B016 | C72: B016@qq.com | D72: 清华大学附属中学 | E72: 田滨诚 | G72: 112 | H72: 100 | I72: 0 | J72: 12
A73: 67 | B73: D026 | C73: D026@qq.com | D73: 杭州市第二中学 | E73: 斯嘉智 | G73: 112 | H73: 100 | I73: 11 | J73: 1
A74: 67 | B74: B028 | C74: B028@qq.com | D74: 成都市锦江区嘉祥外国语高级中学 | E74: 张子佩 | G74: 112 | H74: 100 | I74: 11 | J74: 1
A75: 67 | B75: D025 | C75: D025@qq.com | D75: 北京大学附属中学 | E75: 黄子怀 | G75: 112 | H75: 100 | I75: 11 | J75: 1
A76: 67 | B76: C042 | C76: C042@qq.com | D76: 陕西渭南高新中学 | E76: 张嘉宁 | G76: 112 | H76: 100 | I76: 11 | J76: 1
A77: 76 | B77: B023 | C77: B023@qq.com | D77: 福州第三中学 | E77: 郑锦翼 | G77: 111 | H77: 100 | I77: 11 | J77: 0
A78: 76 | B78: B035 | C78: B035@qq.com | D78: 西安市铁一中学 | E78: 李东宸 | G78: 111 | H78: 100 | I78: 11 | J78: 0
... A99: 97 | B99: B032 | C99: B032@qq.com | D99: 成都市第七中学 | E99: 古皓羽 | G99: 100 | H99: 100 | I99: 0 | J99: 0
A100: 97 | B100: A028 | C100: A028@qq.com | D100: 重庆市第八中学校 | E100: 彭彦桐 | F100: A028 | G100: 100 | H100: 100 | I100: 0 | J100: 0
A101: 97 | B101: B022 | C101: B022@qq.com | D101: 乐山高新区嘉祥外国语学校 | E101: 孙邦博 | G101: 100 | H101: 100 | I101: 0 | J101: 0
A102: 97 | B102: A020 | C102: A020@qq.com | D102: 深圳外国语学校 | E102: 许由 | G102: 100 | H102: 100 | I102: 0 | J102: 0
A103: 97 | B103: A032 | C103: A032@qq.com | D103: 重庆市巴蜀中学校 | E103: 王燨 | G103: 100 | H103: 100 | I103: 0 | J103: 0
A104: 97 | B104: B027 | C104: B027@qq.com | D104: 长沙市第一中学 | E104: 匡宸锐 | G104: 100 | H104: 100 | I104: 0 | J104: 0
A105: 97 | B105: C025 | C105: C025@qq.com | D105: 广州大学附属中学 | E105: 李钧 | G105: 100 | H105: 100 | I105: 0 | J105: 0
A106: 97 | B106: C021 | C106: C021@qq.com | D106: 广东实验中学 | E106: 江牧川 | G106: 100 | H106: 100 | I106: 0 | J106: 0
A107: 97 | B107: C031 | C107: C031@qq.com | D107: 广州大学附属中学 | E107: 缪凌锴 | G107: 100 | H107: 100 | I107: 0 | J107: 0
A108: 97 | B108: D032 | C108: D032@qq.com | D108: 杭州市第二中学 | E108: 贺枳南 | G108: 100 | H108: 100 | I108: 0 | J108: 0
A109: 97 | B109: C040 | C109: C040@qq.com | D109: 广州大学附属中学 | E109: 姚宇翔 | G109: 100 | H109: 100 | I109: 0 | J109: 0
A110: 97 | B110: C034 | C110: C034@qq.com | D110: 广州大学附属中学 | E110: 赵稻道 | G110: 100 | H110: 100 | I110: 0 | J110: 0
A111: 110 | B111: C019 | C111: C019@qq.com | D111: 中山市三鑫学校 | E111: 黄子曜 | G111: 93 | H111: 60 | I111: 11 | J111: 22
...

Sheet Sheet5
A1: # | B1: 用户 | C1: 电子邮件 | D1: 学校 | E1: 名称 | F1: 学号 | G1: 总分数 | H1: #1 路径 | I1: #2 圆桌 | J1: #3 传送门
A2: 1 | B2: A004 | C2: A004@qq.com | D2: 华南师范大学附属中学 | E2: 叶隽霖 | G2: 300 | H2: 100 | I2: 100 | J2: 100
A3: 2 | B3: A007 | C3: A007@qq.com | D3: 上海市曹杨第二中学 | E3: 王翊临 | G3: 232 | H3: 100 | I3: 32 | J3: 100
A4: 2 | B4: B011 | C4: B011@qq.com | D4: 西安市铁一中学 | E4: 李倏嘉 | G4: 232 | H4: 100 | I4: 32 | J4: 100
A5: 2 | B5: A011 | C5: A011@qq.com | D5: 广州大学附属中学 | E5: 张乐涛 | G5: 232 | H5: 100 | I5: 32 | J5: 100
A6: 2 | B6: A010 | C6: A010@qq.com | D6: 浙江省诸暨市海亮高级中学 | E6: 吴旻逸 | G6: 232 | H6: 100 | I6: 32 | J6: 100
A7: 6 | B7: A001 | C7: A001@qq.com | D7: 华南师范大学附属中学 | E7: 戴睿宸 | G7: 230 | H7: 100 | I7: 100 | J7: 30
A8: 6 | B8: A025 | C8: A025@qq.com | D8: 长郡中学 | E8: 程楷轩 | G8: 230 | H8: 100 | I8: 100 | J8: 30
A9: 8 | B9: A014 | C9: A014@qq.com | D9: 上海外国语大学附属外国语学校 | E9: 吴思成 | G9: 220 | H9: 100 | I9: 100 | J9: 20
A10: 9 | B10: B005 | C10: B005@qq.com | D10: 西南大学附属中学校 | E10: 刘恒卓 | G10: 216 | H10: 100 | I10: 16 | J10: 100
A11: 10 | B11: A039 | C11: A039@qq.com | D11: 北京市十一学校 | E11: 方铨铎 | G11: 212 | H11: 100 | I11: 12 | J11: 100
A12: 11 | B12: A023 | C12: A023@qq.com | D12: 浙江省诸暨市海亮高级中学 | E12: 刘家萌 | G12: 210 | H12: 100 | I12: 100 | J12: 10
A13: 12 | B13: A043 | C13: A043@qq.com | D13: 唐山市第一中学 | E13: 范小冉 | G13: 204 | H13: 100 | I13: 74 | J13: 30
... A72: 71 | B72: B036 | C72: B036@qq.com | D72: 浙江省诸暨市海亮高级中学 | E72: 谢汝瑜 | G72: 147 | H72: 95 | I72: 32 | J72: 20
A73: 72 | B73: A028 | C73: A028@qq.com | D73: 重庆市第八中学校 | E73: 彭彦桐 | F73: A028 | G73: 145 | H73: 100 | I73: 45 | J73: 0
A74: 72 | B74: C031 | C74: C031@qq.com | D74: 广州大学附属中学 | E74: 缪凌锴 | G74: 145 | H74: 100 | I74: 45 | J74: 0
A75: 74 | B75: A020 | C75: A020@qq.com | D75: 深圳外国语学校 | E75: 许由 | G75: 143 | H75: 95 | I75: 48 | J75: 0
A76: 75 | B76: C036 | C76: C036@qq.com | D76: 中山市三鑫学校 | E76: 程奕霖 | G76: 142 | H76: 100 | I76: 32 | J76: 10
A77: 75 | B77: C012 | C77: C012@qq.com | D77: 长沙市第一中学 | E77: 王奕博 | G77: 142 | H77: 100 | I77: 32 | J77: 10
A78: 75 | B78: D004 | C78: D004@qq.com | E78: 关永丞 | G78: 142 | H78: 100 | I78: 32 | J78: 10
A79: 75 | B79: C008 | C79: C008@qq.com | D79: 浙江省诸暨市海亮高级中学 | E79: 边逸城 | G79: 142 | H79: 100 | I79: 32 | J79: 10
A80: 75 | B80: B039 | C80: B039@qq.com | D80: 广州大学附属中学 | E80: 梁家齐 | G80: 142 | H80: 100 | I80: 32 | J80: 10
A81: 75 | B81: C007 | C81: C007@qq.com | D81: 广州大学附属中学 | E81: 杨金城 | G81: 142 | H81: 100 | I81: 32 | J81: 10
A82: 81 | B82: B040 | C82: B040@qq.com | D82: 重庆市巴蜀中学校 | E82: 李劭鸿 | G82: 135 | H82: 100 | I82: 35 | J82: 0
A83: 82 | B83: C002 | C83: C002@qq.com | D83: 深圳市耀华实验学校 | E83: 刘航聿 | G83: 132 | H83: 100 | I83: 32 | J83: 0
A84: 82 | B84: B038 | C84: B038@qq.com | D84: 广东实验中学 | E84: 苏昱霖 | G84: 132 | H84: 100 | I84: 32 | J84: 0
A85: 82 | B85: B017 | C85: B017@qq.com | D85: 安徽师范大学附属中学 | E85: 王天琢 | G85: 132 | H85: 100 | I85: 32 | J85: 0
A86: 82 | B86: A015 | C86: A015@qq.com | D86: 华南师范大学附属中学 | E86: 叶名瀚 | G86: 132 | H86: 100 | I86: 32 | J86: 0
A87: 82 | B87: D036 | C87: D036@qq.com | D87: 深圳市福田区红岭中学 | E87: 陈悦扬 | G87: 132 | H87: 100 | I87: 32 | J87: 0
A88: 82 | B88: D022 | C88: D022@qq.com | D88: 中山市石岐中学 | E88: 钟宇杰 | G88: 132 | H88: 100 | I88: 32 | J88: 0
A89: 82 | B89: B032 | C89: B032@qq.com | D89: 成都市第七中学 | E89: 古皓羽 | G89: 132 | H89: 100 | I89: 32 | J89: 0
A90: 82 | B90: B030 | C90: B030@qq.com | D90: 成都外国语学校 | E90: 马周 | G90: 132 | H90: 100 | I90: 32 | J90: 0
... A165: 158 | B165: D042 | C165: D042@qq.com | D165: 广州大学附属中学 | E165: 姚昊佑 | G165: 0 | H165: 0 | I165: 0 | J165: 0

Sheet Sheet6
A1: # | B1: 用户 | C1: 电子邮件 | D1: 学校 | E1: 名称 | F1: 学号 | G1: 总分数 | H1: #1 多彩序列 | I1: #2 大冲刺 | J1: #3 不太像花的基环树
A2: 1 | B2: A043 | C2: A043@qq.com | D2: 唐山市第一中学 | E2: 范小冉 | G2: 300 | H2: 100 | I2: 100 | J2: 100
A3: 1 | B3: A023 | C3: A023@qq.com | D3: 浙江省诸暨市海亮高级中学 | E3: 刘家萌 | G3: 300 | H3: 100 | I3: 100 | J3: 100
A4: 1 | B4: A014 | C4: A014@qq.com | D4: 上海外国语大学附属外国语学校 | E4: 吴思成 | G4: 300 | H4: 100 | I4: 100 | J4: 100
A5: 1 | B5: B001 | C5: B001@qq.com | D5: 上海市曹杨第二中学 | E5: 李烨霖 | G5: 300 | H5: 100 | I5: 100 | J5: 100
A6: 1 | B6: A029 | C6: A029@qq.com | D6: 广州市第六中学 | E6: 练思远 | G6: 300 | H6: 100 | I6: 100 | J6: 100
A7: 1 | B7: A021 | C7: A021@qq.com | D7: 深圳中学 | E7: 李子优 | G7: 300 | H7: 100 | I7: 100 | J7: 100
A8: 1 | B8: C041 | C8: C041@qq.com | D8: 成都市第七中学 | E8: 蒋林逍 | G8: 300 | H8: 100 | I8: 100 | J8: 100
A9: 1 | B9: A024 | C9: A024@qq.com | D9: 佛山市南海区石门中学 | E9: 谢朝阳 | G9: 300 | H9: 100 | I9: 100 | J9: 100
A10: 1 | B10: B033 | C10: B033@qq.com | D10: 华中师范大学第一附属中学 | E10: 柳子宁 | G10: 300 | H10: 100 | I10: 100 | J10: 100
A11: 1 | B11: A010 | C11: A010@qq.com | D11: 浙江省诸暨市海亮高级中学 | E11: 吴旻逸 | G11: 300 | H11: 100 | I11: 100 | J11: 100
A12: 1 | B12: D040 | C12: D040@qq.com | D12: 长沙市第一中学 | E12: 杨济帆 | G12: 300 | H12: 100 | I12: 100 | J12: 100
A13: 1 | B13: A011 | C13: A011@qq.com | D13: 广州大学附属中学 | E13: 张乐涛 | G13: 300 | H13: 100 | I13: 100 | J13: 100
... A54: 53 | B54: A017 | C54: A017@qq.com | D54: 深圳中学 | E54: 朱瀚阳 | G54: 224 | H54: 100 | I54: 100 | J54: 24
A55: 53 | B55: A028 | C55: A028@qq.com | D55: 重庆市第八中学校 | E55: 彭彦桐 | F55: A028 | G55: 224 | H55: 100 | I55: 100 | J55: 24
A56: 53 | B56: D012 | C56: D012@qq.com | D56: 中山市三鑫学校 | E56: 徐浩轩 | G56: 224 | H56: 100 | I56: 100 | J56: 24
A57: 53 | B57: A016 | C57: A016@qq.com | D57: 成都市第七中学 | E57: 邓融阔 | G57: 224 | H57: 100 | I57: 100 | J57: 24
A58: 53 | B58: A031 | C58: A031@qq.com | D58: 华中师范大学第一附属中学 | E58: 伍敬宇 | G58: 224 | H58: 100 | I58: 100 | J58: 24
A59: 53 | B59: B005 | C59: B005@qq.com | D59: 西南大学附属中学校 | E59: 刘恒卓 | G59: 224 | H59: 100 | I59: 100 | J59: 24
A60: 53 | B60: D005 | C60: D005@qq.com | D60: 中山市中山纪念中学 | E60: 阳毅 | G60: 224 | H60: 100 | I60: 100 | J60: 24
A61: 53 | B61: C031 | C61: C031@qq.com | D61: 广州大学附属中学 | E61: 缪凌锴 | G61: 224 | H61: 100 | I61: 100 | J61: 24
A62: 53 | B62: C026 | C62: C026@qq.com | D62: 中山市中山纪念中学 | E62: 崔瑞麟 | G62: 224 | H62: 100 | I62: 100 | J62: 24
A63: 53 | B63: D004 | C63: D004@qq.com | E63: 关永丞 | G63: 224 | H63: 100 | I63: 36 | J63: 88
A64: 53 | B64: D025 | C64: D025@qq.com | D64: 北京大学附属中学 | E64: 黄子怀 | G64: 224 | H64: 100 | I64: 100 | J64: 24
A65: 53 | B65: B015 | C65: B015@qq.com | D65: 杭州市第二中学 | E65: 郑乐章 | G65: 224 | H65: 100 | I65: 100 | J65: 24
A66: 53 | B66: B024 | C66: B024@qq.com | D66: 广东实验中学 | E66: 康立扬 | G66: 224 | H66: 100 | I66: 100 | J66: 24
A67: 66 | B67: A015 | C67: A015@qq.com | D67: 华南师范大学附属中学 | E67: 叶名瀚 | G67: 220 | H67: 100 | I67: 100 | J67: 20
A68: 66 | B68: D041 | C68: D041@qq.com | D68: 稻香湖学校 | E68: 赵云帆 | G68: 220 | H68: 100 | I68: 100 | J68: 20
A69: 66 | B69: C025 | C69: C025@qq.com | D69: 广州大学附属中学 | E69: 李钧 | G69: 220 | H69: 100 | I69: 100 | J69: 20
A70: 69 | B70: B042 | C70: B042@qq.com | D70: 武汉新城实验中学 | E70: 刘珈逸 | G70: 216 | H70: 100 | I70: 100 | J70: 16
A71: 69 | B71: D034 | C71: D034@qq.com | D71: 长沙市中雅培粹学校 | E71: 李学睿 | G71: 216 | H71: 100 | I71: 100 | J71: 16
A72: 69 | B72: D010 | C72: D010@qq.com | D72: 佛山市南海区瀚文外国语学校 | E72: 沈圣添 | G72: 216 | H72: 100 | I72: 100 | J72: 16
A73: 72 | B73: D039 | C73: D039@qq.com | D73: 陕西西北工业大学附属中学 | E73: 杨浩基 | G73: 212 | H73: 100 | I73: 100 | J73: 12
A74: 72 | B74: C018 | C74: C018@qq.com | D74: 深圳中学 | E74: 王中元 | G74: 212 | H74: 100 | I74: 92 | J74: 20
A75: 74 | B75: A018 | C75: A018@qq.com | D75: 中山市三鑫学校 | E75: 袁煜智 | G75: 208 | H75: 100 | I75: 36 | J75: 72
... A164: 159 | B164: A035 | C164: A035@qq.com | D164: 杭州市第二中学 | E164: 周以山 | G164: 0 | H164: 0 | I164: 0 | J164: 0
A165: 159 | B165: valor | C165: valor@qq.com | E165: valor | G165: 0 | H165: 0 | I165: 0 | J165: 0

Sheet Sheet7
A1: # | B1: 用户 | C1: 电子邮件 | D1: 学校 | E1: 名称 | F1: 学号 | G1: 总分数 | H1: #1 超立方体 | I1: #2 地图 II | J1: #3 神谕
A2: 1 | B2: A014 | C2: A014@qq.com | D2: 上海外国语大学附属外国语学校 | E2: 吴思成 | G2: 300 | H2: 100 | I2: 100 | J2: 100
A3: 1 | B3: A016 | C3: A016@qq.com | D3: 成都市第七中学 | E3: 邓融阔 | G3: 300 | H3: 100 | I3: 100 | J3: 100
A4: 3 | B4: A015 | C4: A015@qq.com | D4: 华南师范大学附属中学 | E4: 叶名瀚 | G4: 286 | H4: 100 | I4: 100 | J4: 86
A5: 4 | B5: A031 | C5: A031@qq.com | D5: 华中师范大学第一附属中学 | E5: 伍敬宇 | G5: 285 | H5: 100 | I5: 100 | J5: 85
A6: 5 | B6: A001 | C6: A001@qq.com | D6: 华南师范大学附属中学 | E6: 戴睿宸 | G6: 282 | H6: 100 | I6: 90 | J6: 92
A7: 6 | B7: A010 | C7: A010@qq.com | D7: 浙江省诸暨市海亮高级中学 | E7: 吴旻逸 | G7: 280 | H7: 100 | I7: 100 | J7: 80
A8: 7 | B8: A005 | C8: A005@qq.com | D8: 浙江省诸暨市海亮高级中学 | E8: 贾治辰 | G8: 258 | H8: 100 | I8: 90 | J8: 68
A9: 8 | B9: A007 | C9: A007@qq.com | D9: 上海市曹杨第二中学 | E9: 王翊临 | G9: 245 | H9: 100 | I9: 70 | J9: 75
A10: 9 | B10: A039 | C10: A039@qq.com | D10: 北京市十一学校 | E10: 方铨铎 | G10: 242 | H10: 100 | I10: 100 | J10: 42
A11: 10 | B11: C004 | C11: C004@qq.com | D11: 安徽师范大学附属中学 | E11: 张宗岳 | G11: 240 | H11: 100 | I11: 100 | J11: 40
A12: 10 | B12: B005 | C12: B005@qq.com | D12: 西南大学附属中学校 | E12: 刘恒卓 | G12: 240 | H12: 100 | I12: 90 | J12: 50
A13: 10 | B13: D034 | C13: D034@qq.com | D13: 长沙市中雅培粹学校 | E13: 李学睿 | G13: 240 | H13: 100 | I13: 100 | J13: 40
... A27: 23 | B27: B033 | C27: B033@qq.com | D27: 华中师范大学第一附属中学 | E27: 柳子宁 | G27: 214 | H27: 100 | I27: 100 | J27: 14
A28: 27 | B28: A028 | C28: A028@qq.com | D28: 重庆市第八中学校 | E28: 彭彦桐 | F28: A028 | G28: 209 | H28: 100 | I28: 90 | J28: 19
A29: 28 | B29: C011 | C29: C011@qq.com | D29: 华南师范大学附属中学 | E29: 卢逸轩 | G29: 204 | H29: 100 | I29: 60 | J29: 44
A30: 28 | B30: C028 | C30: C028@qq.com | D30: 广州大学附属中学 | E30: 陈瀚熹 | G30: 204 | H30: 100 | I30: 90 | J30: 14
A31: 30 | B31: A020 | C31: A020@qq.com | D31: 深圳外国语学校 | E31: 许由 | G31: 203 | H31: 100 | I31: 90 | J31: 13
A32: 31 | B32: B017 | C32: B017@qq.com | D32: 安徽师范大学附属中学 | E32: 王天琢 | G32: 202 | H32: 100 | I32: 60 | J32: 42
A33: 31 | B33: A025 | C33: A025@qq.com | D33: 长郡中学 | E33: 程楷轩 | G33: 202 | H33: 100 | I33: 60 | J33: 42
A34: 33 | B34: B008 | C34: B008@qq.com | D34: 北京大学附属中学 | E34: 许远正 | G34: 200 | H34: 100 | I34: 100 | J34: 0
A35: 33 | B35: A038 | C35: A038@qq.com | D35: 广州大学附属中学 | E35: 黄豆 | G35: 200 | H35: 100 | I35: 90 | J35: 10
A36: 33 | B36: A006 | C36: A006@qq.com | D36: 华南师范大学附属中学 | E36: 李承翰 | G36: 200 | H36: 100 | I36: 100 | J36: 0
A37: 33 | B37: A009 | C37: A009@qq.com | D37: 成都外国语学校 | E37: 蒋明睿 | G37: 200 | H37: 100 | I37: 100 | J37: 0
A38: 37 | B38: C019 | C38: C019@qq.com | D38: 中山市三鑫学校 | E38: 黄子曜 | G38: 194 | H38: 100 | I38: 10 | J38: 84
A39: 37 | B39: C030 | C39: C030@qq.com | D39: 广东实验中学 | E39: 林轩睿 | G39: 194 | H39: 100 | I39: 80 | J39: 14
A40: 39 | B40: A008 | C40: A008@qq.com | D40: 广州市第二中学 | E40: 范璟阳 | G40: 190 | H40: 100 | I40: 90 | J40: 0
... A45: 44 | B45: A041 | C45: A041@qq.com | D45: 中山市中山纪念中学 | E45: 周祎 | G45: 184 | H45: 100 | I45: 70 | J45: 14
A46: 44 | B46: D004 | C46: D004@qq.com | E46: 关永丞 | G46: 184 | H46: 100 | I46: 60 | J46: 24
A47: 44 | B47: B028 | C47: B028@qq.com | D47: 成都市锦江区嘉祥外国语高级中学 | E47: 张子佩 | G47: 184 | H47: 100 | I47: 70 | J47: 14
A48: 47 | B48: A021 | C48: A021@qq.com | D48: 深圳中学 | E48: 李子优 | G48: 182 | H48: 100 | I48: 40 | J48: 42
A49: 48 | B49: B011 | C49: B011@qq.com | D49: 西安市铁一中学 | E49: 李倏嘉 | G49: 178 | H49: 100 | I49: 0 | J49: 78
A50: 49 | B50: C039 | C50: C039@qq.com | D50: 中山市纪雅学校 | E50: 全智贤 | G50: 175 | H50: 100 | I50: 0 | J50: 75
A51: 50 | B51: B001 | C51: B001@qq.com | D51: 上海市曹杨第二中学 | E51: 李烨霖 | G51: 172 | H51: 100 | I51: 30 | J51: 42
A52: 51 | B52: C041 | C52: C041@qq.com | D52: 成都市第七中学 | E52: 蒋林逍 | G52: 170 | H52: 100 | I52: 70 | J52: 0
A53: 52 | B53: D019 | C53: D019@qq.com | D53: 清远市广铁一中（万科城）外国语学校 | E53: 何致远 | G53: 162 | H53: 100 | I53: 20 | J53: 42
A54: 53 | B54: D039 | C54: D039@qq.com | D54: 陕西西北工业大学附属中学 | E54: 杨浩基 | G54: 160 | H54: 100 | I54: 60 | J54: 0
A55: 53 | B55: A033 | C55: A033@qq.com | D55: 广州市铁一中学 | E55: 于镓赫 | G55: 160 | H55: 100 | I55: 60 | J55: 0
A56: 53 | B56: A030 | C56: A030@qq.com | D56: 北京市十一学校 | E56: 陈信允 | G56: 160 | H56: 100 | I56: 60 | J56: 0
A57: 53 | B57: C015 | C57: C015@qq.com | D57: 安徽师范大学附属中学 | E57: 赵旭初 | G57: 160 | H57: 100 | I57: 60 | J57: 0
...

Sheet Sheet8
A1: # | B1: 用户 | C1: 电子邮件 | D1: 学校 | E1: 名称 | F1: 学号 | G1: 总分数 | H1: #1 游戏 | I1: #2 建设 | J1: #3 Cycle Of Sorrow
A2: 1 | B2: A023 | C2: A023@qq.com | D2: 浙江省诸暨市海亮高级中学 | E2: 刘家萌 | G2: 260 | H2: 100 | I2: 100 | J2: 60
A3: 2 | B3: A010 | C3: A010@qq.com | D3: 浙江省诸暨市海亮高级中学 | E3: 吴旻逸 | G3: 250 | H3: 100 | I3: 100 | J3: 50
A4: 3 | B4: A028 | C4: A028@qq.com | D4: 重庆市第八中学校 | E4: 彭彦桐 | F4: A028 | G4: 225 | H4: 100 | I4: 100 | J4: 25
A5: 4 | B5: A036 | C5: A036@qq.com | D5: 佛山市南海区石门中学 | E5: 王梓睿 | G5: 215 | H5: 100 | I5: 100 | J5: 15
A6: 5 | B6: A009 | C6: A009@qq.com | D6: 成都外国语学校 | E6: 蒋明睿 | G6: 210 | H6: 100 | I6: 100 | J6: 10
A7: 5 | B7: A001 | C7: A001@qq.com | D7: 华南师范大学附属中学 | E7: 戴睿宸 | G7: 210 | H7: 100 | I7: 65 | J7: 45
A8: 5 | B8: A011 | C8: A011@qq.com | D8: 广州大学附属中学 | E8: 张乐涛 | G8: 210 | H8: 100 | I8: 65 | J8: 45
A9: 8 | B9: A014 | C9: A014@qq.com | D9: 上海外国语大学附属外国语学校 | E9: 吴思成 | G9: 200 | H9: 100 | I9: 65 | J9: 35
A10: 8 | B10: B005 | C10: B005@qq.com | D10: 西南大学附属中学校 | E10: 刘恒卓 | G10: 200 | H10: 100 | I10: 65 | J10: 35
A11: 8 | B11: A043 | C11: A043@qq.com | D11: 唐山市第一中学 | E11: 范小冉 | G11: 200 | H11: 100 | I11: 100 | J11: 0
A12: 11 | B12: A002 | C12: A002@qq.com | D12: 重庆市巴蜀中学校 | E12: 殷骏 | G12: 185 | H12: 100 | I12: 65 | J12: 20
A13: 12 | B13: A015 | C13: A015@qq.com | D13: 华南师范大学附属中学 | E13: 叶名瀚 | G13: 180 | H13: 100 | I13: 65 | J13: 15
A14: 12 | B14: A038 | C14: A038@qq.com | D14: 广州大学附属中学 | E14: 黄豆 | G14: 180 | H14: 100 | I14: 65 | J14: 15
A15: 14 | B15: B041 | C15: B041@qq.com | D15: 福建省厦门第一中学 | E15: 张子朴 | G15: 170 | H15: 100 | I15: 70 | J15: 0
A16: 15 | B16: A024 | C16: A024@qq.com | D16: 佛山市南海区石门中学 | E16: 谢朝阳 | G16: 165 | H16: 100 | I16: 65 | J16: 0
... A53: 51 | B53: C002 | C53: C002@qq.com | D53: 深圳市耀华实验学校 | E53: 刘航聿 | G53: 120 | H53: 100 | I53: 0 | J53: 20
A54: 51 | B54: D004 | C54: D004@qq.com | E54: 关永丞 | G54: 120 | H54: 100 | I54: 0 | J54: 20
A55: 51 | B55: C006 | C55: C006@qq.com | D55: 广东实验中学 | E55: 汪嘉睿 | G55: 120 | H55: 100 | I55: 0 | J55: 20
A56: 55 | B56: D040 | C56: D040@qq.com | D56: 长沙市第一中学 | E56: 杨济帆 | G56: 115 | H56: 100 | I56: 15 | J56: 0
A57: 55 | B57: A029 | C57: A029@qq.com | D57: 广州市第六中学 | E57: 练思远 | G57: 115 | H57: 100 | I57: 0 | J57: 15
A58: 55 | B58: B024 | C58: B024@qq.com | D58: 广东实验中学 | E58: 康立扬 | G58: 115 | H58: 100 | I58: 0 | J58: 15
A59: 55 | B59: C019 | C59: C019@qq.com | D59: 中山市三鑫学校 | E59: 黄子曜 | G59: 115 | H59: 100 | I59: 15 | J59: 0
A60: 59 | B60: B036 | C60: B036@qq.com | D60: 浙江省诸暨市海亮高级中学 | E60: 谢汝瑜 | G60: 110 | H60: 100 | I60: 10 | J60: 0
A61: 59 | B61: B025 | C61: B025@qq.com | D61: 中山市中山纪念中学 | E61: 邓承羽 | G61: 110 | H61: 100 | I61: 0 | J61: 10
A62: 59 | B62: A041 | C62: A041@qq.com | D62: 中山市中山纪念中学 | E62: 周祎 | G62: 110 | H62: 100 | I62: 10 | J62: 0
A63: 59 | B63: A033 | C63: A033@qq.com | D63: 广州市铁一中学 | E63: 于镓赫 | G63: 110 | H63: 100 | I63: 0 | J63: 10
A64: 59 | B64: C018 | C64: C018@qq.com | D64: 深圳中学 | E64: 王中元 | G64: 110 | H64: 100 | I64: 10 | J64: 0
A65: 59 | B65: B007 | C65: B007@qq.com | D65: 北京大学附属中学 | E65: 陈一苇 | G65: 110 | H65: 100 | I65: 0 | J65: 10
A66: 59 | B66: B018 | C66: B018@qq.com | D66: 重庆市育才中学校 | E66: 周琛乔 | G66: 110 | H66: 100 | I66: 0 | J66: 10
... A163: 148 | B163: D033 | C163: D033@qq.com | D163: 杭州市第二中学 | E163: 陈元熙 | G163: 0 | H163: 0 | I163: 0 | J163: 0

Sheet Summary
A1: 用户 | B1: 学校 | C1: 名称 | D1: Contest 1 | J1: Contest 2 | P1: Contest 3 | V1: Contest 4 | AB1: C1 总分 | AC1: C2 总分 | AD1: C3 总分 | AE1: C4 总分 | AF1: 总分 | AG1: 排名
D2: Day 1 | G2: Day 2 | J2: Day 1 | M2: Day 2 | P2: Day 1 | S2: Day 2 | V2: Day 1 | Y2: Day 2
D3: T1 信号连接 | E3: T2 谜题 | F3: T3 最古老的传说 | G3: T1 猪染色 | H3: T2 猪相遇 | I3: T3 猪画画 | J3: T1 双飞燕 | K3: T2 裹锋 | L3: T3 气合 | M3: T1 双生棋子 | N3: T2 死亡路线 | O3: T3 夜空奏 | P3: T1 路径 | Q3: T2 圆桌 | R3: T3 传送门 | S3: T1 多彩序列 | T3: T2 大冲刺 | U3: T3 不太像花的基环树 | V3: T1 超立方体 | W3: T2 地图II | X3: T3 神谕 | Y3: T1 游戏 | Z3: T2 建设 | AA3: T3 CycleOfSorrow
A4: A001 | B4: =_xlfn.XLOOKUP($A4,Sheet3!$B:$B,Sheet3!D:D) -> 华南师范大学附属中学 | C4: =_xlfn.XLOOKUP($A4,Sheet3!$B:$B,Sheet3!E:E) -> 戴睿宸 | D4: =_xlfn.XLOOKUP($A4,Sheet1!$B:$B,Sheet1!H:H) -> 100 | E4: =_xlfn.XLOOKUP($A4,Sheet1!$B:$B,Sheet1!I:I) -> 100 | F4: =_xlfn.XLOOKUP($A4,Sheet1!$B:$B,Sheet1!J:J) -> 25 | G4: =_xlfn.XLOOKUP($A4,Sheet2!$B:$B,Sheet2!H:H) -> 100 | H4: =_xlfn.XLOOKUP($A4,Sheet2!$B:$B,Sheet2!I:I) -> 56 | I4: =_xlfn.XLOOKUP($A4,Sheet2!$B:$B,Sheet2!J:J) -> 24 | J4: =_xlfn.XLOOKUP($A4,Sheet3!$B:$B,Sheet3!H:H) -> 100 | K4: =_xlfn.XLOOKUP($A4,Sheet3!$B:$B,Sheet3!I:I) -> 100 | L4: =_xlfn.XLOOKUP($A4,Sheet3!$B:$B,Sheet3!J:J) -> 40 | M4: =_xlfn.XLOOKUP($A4,Sheet4!$B:$B,Sheet4!H:H) -> 100 | N4: =_xlfn.XLOOKUP($A4,Sheet4!$B:$B,Sheet4!I:I) -> 100 | O4: =_xlfn.XLOOKUP($A4,Sheet4!$B:$B,Sheet4!J:J) -> 69 | P4: =_xlfn.XLOOKUP($A4,Sheet5!$B:$B,Sheet5!H:H) -> 100 | Q4: =_xlfn.XLOOKUP($A4,Sheet5!$B:$B,Sheet5!I:I) -> 100 | R4: =_xlfn.XLOOKUP($A4,Sheet5!$B:$B,Sheet5!J:J) -> 30 | S4: =_xlfn.XLOOKUP($A4,Sheet6!$B:$B,Sheet6!H:H) -> 100 | T4: =_xlfn.XLOOKUP($A4,Sheet6!$B:$B,Sheet6!I:I) -> 100 | U4: =_xlfn.XLOOKUP($A4,Sheet6!$B:$B,Sheet6!J:J) -> 100 | V4: =_xlfn.XLOOKUP($A4,Sheet7!$B:$B,Sheet7!H:H) -> 100 | W4: =_xlfn.XLOOKUP($A4,Sheet7!$B:$B,Sheet7!I:I) -> 90 | X4: =_xlfn.XLOOKUP($A4,Sheet7!$B:$B,Sheet7!J:J) -> 92 | Y4: =_xlfn.XLOOKUP($A4,Sheet8!$B:$B,Sheet8!H:H) -> 100 | Z4: =_xlfn.XLOOKUP($A4,Sheet8!$B:$B,Sheet8!I:I) -> 65 | AA4: =_xlfn.XLOOKUP($A4,Sheet8!$B:$B,Sheet8!J:J) -> 45 | AB4: =_xlfn.XLOOKUP($A4,Sheet1!$B:$B,Sheet1!G:G,0)+_xlfn.XLOOKUP($A4,Sheet2!$B:$B,Sheet2!G:G,0) -> 405 | AC4: =_xlfn.XLOOKUP($A4,Sheet3!$B:$B,Sheet3!G:G,0)+_xlfn.XLOOKUP($A4,Sheet4!$B:$B,Sheet4!G:G,0) -> 509 | AD4: =_xlfn.XLOOKUP($A4,Sheet5!$B:$B,Sheet5!G:G,0)+_xlfn.XLOOKUP($A4,Sheet6!$B:$B,Sheet6!G:G,0) -> 530 | AE4: =_xlfn.XLOOKUP($A4,Sheet7!$B:$B,Sheet7!G:G,0)+_xlfn.XLOOKUP($A4,Sheet8!$B:$B,Sheet8!G:G,0) -> 492 | AF4: {=SUM(IFERROR(AB4:AE4,0))} -> 1936 | AG4: =RANK(AF4, $AF$4:$AF$166) -> 1
A5: A036 | B5: =_xlfn.XLOOKUP($A5,Sheet3!$B:$B,Sheet3!D:D) -> 佛山市南海区石门中学 | C5: =_xlfn.XLOOKUP($A5,Sheet3!$B:$B,Sheet3!E:E) -> 王梓睿 | D5: =_xlfn.XLOOKUP($A5,Sheet1!$B:$B,Sheet1!H:H) -> 100 | E5: =_xlfn.XLOOKUP($A5,Sheet1!$B:$B,Sheet1!I:I) -> 66 | F5: =_xlfn.XLOOKUP($A5,Sheet1!$B:$B,Sheet1!J:J) -> 100 | G5: =_xlfn.XLOOKUP($A5,Sheet2!$B:$B,Sheet2!H:H) -> 100 | H5: =_xlfn.XLOOKUP($A5,Sheet2!$B:$B,Sheet2!I:I) -> 100 | I5: =_xlfn.XLOOKUP($A5,Sheet2!$B:$B,Sheet2!J:J) -> 33 | J5: =_xlfn.XLOOKUP($A5,Sheet3!$B:$B,Sheet3!H:H) -> 100 | K5: =_xlfn.XLOOKUP($A5,Sheet3!$B:$B,Sheet3!I:I) -> 100 | L5: =_xlfn.XLOOKUP($A5,Sheet3!$B:$B,Sheet3!J:J) -> 70 | M5: =_xlfn.XLOOKUP($A5,Sheet4!$B:$B,Sheet4!H:H) -> 100 | N5: =_xlfn.XLOOKUP($A5,Sheet4!$B:$B,Sheet4!I:I) -> 95 | O5: =_xlfn.XLOOKUP($A5,Sheet4!$B:$B,Sheet4!J:J) -> 100 | P5: =_xlfn.XLOOKUP($A5,Sheet5!$B:$B,Sheet5!H:H) -> 100 | Q5: =_xlfn.XLOOKUP($A5,Sheet5!$B:$B,Sheet5!I:I) -> 74 | R5: =_xlfn.XLOOKUP($A5,Sheet5!$B:$B,Sheet5!J:J) -> 30 | S5: =_xlfn.XLOOKUP($A5,Sheet6!$B:$B,Sheet6!H:H) -> 100 | T5: =_xlfn.XLOOKUP($A5,Sheet6!$B:$B,Sheet6!I:I) -> 100 | U5: =_xlfn.XLOOKUP($A5,Sheet6!$B:$B,Sheet6!J:J) -> 100 | V5: =_xlfn.XLOOKUP($A5,Sheet7!$B:$B,Sheet7!H:H) -> 100 | W5: =_xlfn.XLOOKUP($A5,Sheet7!$B:$B,Sheet7!I:I) -> 30 | X5: =_xlfn.XLOOKUP($A5,Sheet7!$B:$B,Sheet7!J:J) -> 14 | Y5: =_xlfn.XLOOKUP($A5,Sheet8!$B:$B,Sheet8!H:H) -> 100 | Z5: =_xlfn.XLOOKUP($A5,Sheet8!$B:$B,Sheet8!I:I) -> 100 | AA5: =_xlfn.XLOOKUP($A5,Sheet8!$B:$B,Sheet8!J:J) -> 15 | AB5: =_xlfn.XLOOKUP($A5,Sheet1!$B:$B,Sheet1!G:G,0)+_xlfn.XLOOKUP($A5,Sheet2!$B:$B,Sheet2!G:G,0) -> 499 | AC5: =_xlfn.XLOOKUP($A5,Sheet3!$B:$B,Sheet3!G:G,0)+_xlfn.XLOOKUP($A5,Sheet4!$B:$B,Sheet4!G:G,0) -> 565 | AD5: =_xlfn.XLOOKUP($A5,Sheet5!$B:$B,Sheet5!G:G,0)+_xlfn.XLOOKUP($A5,Sheet6!$B:$B,Sheet6!G:G,0) -> 504 | AE5: =_xlfn.XLOOKUP($A5,Sheet7!$B:$B,Sheet7!G:G,0)+_xlfn.XLOOKUP($A5,Sheet8!$B:$B,Sheet8!G:G,0) -> 359 | AF5: {=SUM(IFERROR(AB5:AE5,0))} -> 1927 | AG5: =RANK(AF5, $AF$4:$AF$166) -> 2
A6: A010 | B6: =_xlfn.XLOOKUP($A6,Sheet3!$B:$B,Sheet3!D:D) -> 浙江省诸暨市海亮高级中学 | C6: =_xlfn.XLOOKUP($A6,Sheet3!$B:$B,Sheet3!E:E) -> 吴旻逸 | D6: =_xlfn.XLOOKUP($A6,Sheet1!$B:$B,Sheet1!H:H) -> 100 | E6: =_xlfn.XLOOKUP($A6,Sheet1!$B:$B,Sheet1!I:I) -> 100 | F6: =_xlfn.XLOOKUP($A6,Sheet1!$B:$B,Sheet1!J:J) -> 0 | G6: =_xlfn.XLOOKUP($A6,Sheet2!$B:$B,Sheet2!H:H) -> 100 | H6: =_xlfn.XLOOKUP($A6,Sheet2!$B:$B,Sheet2!I:I) -> 56 | I6: =_xlfn.XLOOKUP($A6,Sheet2!$B:$B,Sheet2!J:J) -> 34 | J6: =_xlfn.XLOOKUP($A6,Sheet3!$B:$B,Sheet3!H:H) -> 84 | K6: =_xlfn.XLOOKUP($A6,Sheet3!$B:$B,Sheet3!I:I) -> 100 | L6: =_xlfn.XLOOKUP($A6,Sheet3!$B:$B,Sheet3!J:J) -> 40 | M6: =_xlfn.XLOOKUP($A6,Sheet4!$B:$B,Sheet4!H:H) -> 100 | N6: =_xlfn.XLOOKUP($A6,Sheet4!$B:$B,Sheet4!I:I) -> 0 | O6: =_xlfn.XLOOKUP($A6,Sheet4!$B:$B,Sheet4!J:J) -> 100 | P6: =_xlfn.XLOOKUP($A6,Sheet5!$B:$B,Sheet5!H:H) -> 100 | Q6: =_xlfn.XLOOKUP($A6,Sheet5!$B:$B,Sheet5!I:I) -> 32 | R6: =_xlfn.XLOOKUP($A6,Sheet5!$B:$B,Sheet5!J:J) -> 100 | S6: =_xlfn.XLOOKUP($A6,Sheet6!$B:$B,Sheet6!H:H) -> 100 | T6: =_xlfn.XLOOKUP($A6,Sheet6!$B:$B,Sheet6!I:I) -> 100 | U6: =_xlfn.XLOOKUP($A6,Sheet6!$B:$B,Sheet6!J:J) -> 100 | V6: =_xlfn.XLOOKUP($A6,Sheet7!$B:$B,Sheet7!H:H) -> 100 | W6: =_xlfn.XLOOKUP($A6,Sheet7!$B:$B,Sheet7!I:I) -> 100 | X6: =_xlfn.XLOOKUP($A6,Sheet7!$B:$B,Sheet7!J:J) -> 80 | Y6: =_xlfn.XLOOKUP($A6,Sheet8!$B:$B,Sheet8!H:H) -> 100 | Z6: =_xlfn.XLOOKUP($A6,Sheet8!$B:$B,Sheet8!I:I) -> 100 | AA6: =_xlfn.XLOOKUP($A6,Sheet8!$B:$B,Sheet8!J:J) -> 50 | AB6: =_xlfn.XLOOKUP($A6,Sheet1!$B:$B,Sheet1!G:G,0)+_xlfn.XLOOKUP($A6,Sheet2!$B:$B,Sheet2!G:G,0) -> 390 | AC6: =_xlfn.XLOOKUP($A6,Sheet3!$B:$B,Sheet3!G:G,0)+_xlfn.XLOOKUP($A6,Sheet4!$B:$B,Sheet4!G:G,0) -> 424 | AD6: =_xlfn.XLOOKUP($A6,Sheet5!$B:$B,Sheet5!G:G,0)+_xlfn.XLOOKUP($A6,Sheet6!$B:$B,Sheet6!G:G,0) -> 532 | AE6: =_xlfn.XLOOKUP($A6,Sheet7!$B:$B,Sheet7!G:G,0)+_xlfn.XLOOKUP($A6,Sheet8!$B:$B,Sheet8!G:G,0) -> 530 | AF6: {=SUM(IFERROR(AB6:AE6,0))} -> 1876 | AG6: =RANK(AF6, $AF$4:$AF$166) -> 3
A7: A023 | B7: =_xlfn.XLOOKUP($A7,Sheet3!$B:$B,Sheet3!D:D) -> 浙江省诸暨市海亮高级中学 | C7: =_xlfn.XLOOKUP($A7,Sheet3!$B:$B,Sheet3!E:E) -> 刘家萌 | D7: =_xlfn.XLOOKUP($A7,Sheet1!$B:$B,Sheet1!H:H) -> 24 | E7: =_xlfn.XLOOKUP($A7,Sheet1!$B:$B,Sheet1!I:I) -> 100 | F7: =_xlfn.XLOOKUP($A7,Sheet1!$B:$B,Sheet1!J:J) -> 0 | G7: =_xlfn.XLOOKUP($A7,Sheet2!$B:$B,Sheet2!H:H) -> 100 | H7: =_xlfn.XLOOKUP($A7,Sheet2!$B:$B,Sheet2!I:I) -> 0 | I7: =_xlfn.XLOOKUP($A7,Sheet2!$B:$B,Sheet2!J:J) -> 43 | J7: =_xlfn.XLOOKUP($A7,Sheet3!$B:$B,Sheet3!H:H) -> 100 | K7: =_xlfn.XLOOKUP($A7,Sheet3!$B:$B,Sheet3!I:I) -> 100 | L7: =_xlfn.XLOOKUP($A7,Sheet3!$B:$B,Sheet3!J:J) -> 100 | M7: =_xlfn.XLOOKUP($A7,Sheet4!$B:$B,Sheet4!H:H) -> 100 | N7: =_xlfn.XLOOKUP($A7,Sheet4!$B:$B,Sheet4!I:I) -> 100 | O7: =_xlfn.XLOOKUP($A7,Sheet4!$B:$B,Sheet4!J:J) -> 100 | P7: =_xlfn.XLOOKUP($A7,Sheet5!$B:$B,Sheet5!H:H) -> 100 | Q7: =_xlfn.XLOOKUP($A7,Sheet5!$B:$B,Sheet5!I:I) -> 100 | R7: =_xlfn.XLOOKUP($A7,Sheet5!$B:$B,Sheet5!J:J) -> 10 | S7: =_xlfn.XLOOKUP($A7,Sheet6!$B:$B,Sheet6!H:H) -> 100 | T7: =_xlfn.XLOOKUP($A7,Sheet6!$B:$B,Sheet6!I:I) -> 100 | U7: =_xlfn.XLOOKUP($A7,Sheet6!$B:$B,Sheet6!J:J) -> 100 | V7: =_xlfn.XLOOKUP($A7,Sheet7!$B:$B,Sheet7!H:H) -> 100 | W7: =_xlfn.XLOOKUP($A7,Sheet7!$B:$B,Sheet7!I:I) -> 100 | X7: =_xlfn.XLOOKUP($A7,Sheet7!$B:$B,Sheet7!J:J) -> 14 | Y7: =_xlfn.XLOOKUP($A7,Sheet8!$B:$B,Sheet8!H:H) -> 100 | Z7: =_xlfn.XLOOKUP($A7,Sheet8!$B:$B,Sheet8!I:I) -> 100 | AA7: =_xlfn.XLOOKUP($A7,Sheet8!$B:$B,Sheet8!J:J) -> 60 | AB7: =_xlfn.XLOOKUP($A7,Sheet1!$B:$B,Sheet1!G:G,0)+_xlfn.XLOOKUP($A7,Sheet2!$B:$B,Sheet2!G:G,0) -> 267 | AC7: =_xlfn.XLOOKUP($A7,Sheet3!$B:$B,Sheet3!G:G,0)+_xlfn.XLOOKUP($A7,Sheet4!$B:$B,Sheet4!G:G,0) -> 600 | AD7: =_xlfn.XLOOKUP($A7,Sheet5!$B:$B,Sheet5!G:G,0)+_xlfn.XLOOKUP($A7,Sheet6!$B:$B,Sheet6!G:G,0) -> 510 | AE7: =_xlfn.XLOOKUP($A7,Sheet7!$B:$B,Sheet7!G:G,0)+_xlfn.XLOOKUP($A7,Sheet8!$B:$B,Sheet8!G:G,0) -> 474 | AF7: {=SUM(IFERROR(AB7:AE7,0))} -> 1851 | AG7: =RANK(AF7, $AF$4:$AF$166) -> 4
A8: A014 | B8: =_xlfn.XLOOKUP($A8,Sheet3!$B:$B,Sheet3!D:D) -> 上海外国语大学附属外国语学校 | C8: =_xlfn.XLOOKUP($A8,Sheet3!$B:$B,Sheet3!E:E) -> 吴思成 | D8: =_xlfn.XLOOKUP($A8,Sheet1!$B:$B,Sheet1!H:H) -> 42 | E8: =_xlfn.XLOOKUP($A8,Sheet1!$B:$B,Sheet1!I:I) -> 100 | F8: =_xlfn.XLOOKUP($A8,Sheet1!$B:$B,Sheet1!J:J) -> 0 | G8: =_xlfn.XLOOKUP($A8,Sheet2!$B:$B,Sheet2!H:H) -> 100 | H8: =_xlfn.XLOOKUP($A8,Sheet2!$B:$B,Sheet2!I:I) -> 76 | I8: =_xlfn.XLOOKUP($A8,Sheet2!$B:$B,Sheet2!J:J) -> 25 | J8: =_xlfn.XLOOKUP($A8,Sheet3!$B:$B,Sheet3!H:H) -> 100 | K8: =_xlfn.XLOOKUP($A8,Sheet3!$B:$B,Sheet3!I:I) -> 100 | L8: =_xlfn.XLOOKUP($A8,Sheet3!$B:$B,Sheet3!J:J) -> 100 | M8: =_xlfn.XLOOKUP($A8,Sheet4!$B:$B,Sheet4!H:H) -> 100 | N8: =_xlfn.XLOOKUP($A8,Sheet4!$B:$B,Sheet4!I:I) -> 11 | O8: =_xlfn.XLOOKUP($A8,Sheet4!$B:$B,Sheet4!J:J) -> 22 | P8: =_xlfn.XLOOKUP($A8,Sheet5!$B:$B,Sheet5!H:H) -> 100 | Q8: =_xlfn.XLOOKUP($A8,Sheet5!$B:$B,Sheet5!I:I) -> 100 | R8: =_xlfn.XLOOKUP($A8,Sheet5!$B:$B,Sheet5!J:J) -> 20 | S8: =_xlfn.XLOOKUP($A8,Sheet6!$B:$B,Sheet6!H:H) -> 100 | T8: =_xlfn.XLOOKUP($A8,Sheet6!$B:$B,Sheet6!I:I) -> 100 | U8: =_xlfn.XLOOKUP($A8,Sheet6!$B:$B,Sheet6!J:J) -> 100 | V8: =_xlfn.XLOOKUP($A8,Sheet7!$B:$B,Sheet7!H:H) -> 100 | W8: =_xlfn.XLOOKUP($A8,Sheet7!$B:$B,Sheet7!I:I) -> 100 | X8: =_xlfn.XLOOKUP($A8,Sheet7!$B:$B,Sheet7!J:J) -> 100 | Y8: =_xlfn.XLOOKUP($A8,Sheet8!$B:$B,Sheet8!H:H) -> 100 | Z8: =_xlfn.XLOOKUP($A8,Sheet8!$B:$B,Sheet8!I:I) -> 65 | AA8: =_xlfn.XLOOKUP($A8,Sheet8!$B:$B,Sheet8!J:J) -> 35 | AB8: =_xlfn.XLOOKUP($A8,Sheet1!$B:$B,Sheet1!G:G,0)+_xlfn.XLOOKUP($A8,Sheet2!$B:$B,Sheet2!G:G,0) -> 343 | AC8: =_xlfn.XLOOKUP($A8,Sheet3!$B:$B,Sheet3!G:G,0)+_xlfn.XLOOKUP($A8,Sheet4!$B:$B,Sheet4!G:G,0) -> 433 | AD8: =_xlfn.XLOOKUP($A8,Sheet5!$B:$B,Sheet5!G:G,0)+_xlfn.XLOOKUP($A8,Sheet6!$B:$B,Sheet6!G:G,0) -> 520 | AE8: =_xlfn.XLOOKUP($A8,Sheet7!$B:$B,Sheet7!G:G,0)+_xlfn.XLOOKUP($A8,Sheet8!$B:$B,Sheet8!G:G,0) -> 500 | AF8: {=SUM(IFERROR(AB8:AE8,0))} -> 1796 | AG8: =RANK(AF8, $AF$4:$AF$166) -> 5
A9: A002 | B9: =_xlfn.XLOOKUP($A9,Sheet3!$B:$B,Sheet3!D:D) -> 重庆市巴蜀中学校 | C9: =_xlfn.XLOOKUP($A9,Sheet3!$B:$B,Sheet3!E:E) -> 殷骏 | D9: =_xlfn.XLOOKUP($A9,Sheet1!$B:$B,Sheet1!H:H) -> 100 | E9: =_xlfn.XLOOKUP($A9,Sheet1!$B:$B,Sheet1!I:I) -> 100 | F9: =_xlfn.XLOOKUP($A9,Sheet1!$B:$B,Sheet1!J:J) -> 18 | G9: =_xlfn.XLOOKUP($A9,Sheet2!$B:$B,Sheet2!H:H) -> 100 | H9: =_xlfn.XLOOKUP($A9,Sheet2!$B:$B,Sheet2!I:I) -> 56 | I9: =_xlfn.XLOOKUP($A9,Sheet2!$B:$B,Sheet2!J:J) -> 12 | J9: =_xlfn.XLOOKUP($A9,Sheet3!$B:$B,Sheet3!H:H) -> 100 | K9: =_xlfn.XLOOKUP($A9,Sheet3!$B:$B,Sheet3!I:I) -> 100 | L9: =_xlfn.XLOOKUP($A9,Sheet3!$B:$B,Sheet3!J:J) -> 100 | M9: =_xlfn.XLOOKUP($A9,Sheet4!$B:$B,Sheet4!H:H) -> 100 | N9: =_xlfn.XLOOKUP($A9,Sheet4!$B:$B,Sheet4!I:I) -> 100 | O9: =_xlfn.XLOOKUP($A9,Sheet4!$B:$B,Sheet4!J:J) -> 22 | P9: =_xlfn.XLOOKUP($A9,Sheet5!$B:$B,Sheet5!H:H) -> 100 | Q9: =_xlfn.XLOOKUP($A9,Sheet5!$B:$B,Sheet5!I:I) -> 32 | R9: =_xlfn.XLOOKUP($A9,Sheet5!$B:$B,Sheet5!J:J) -> 30 | S9: =_xlfn.XLOOKUP($A9,Sheet6!$B:$B,Sheet6!H:H) -> 100 | T9: =_xlfn.XLOOKUP($A9,Sheet6!$B:$B,Sheet6!I:I) -> 100 | U9: =_xlfn.XLOOKUP($A9,Sheet6!$B:$B,Sheet6!J:J) -> 100 | V9: =_xlfn.XLOOKUP($A9,Sheet7!$B:$B,Sheet7!H:H) -> 100 | W9: =_xlfn.XLOOKUP($A9,Sheet7!$B:$B,Sheet7!I:I) -> 80 | X9: =_xlfn.XLOOKUP($A9,Sheet7!$B:$B,Sheet7!J:J) -> 42 | Y9: =_xlfn.XLOOKUP($A9,Sheet8!$B:$B,Sheet8!H:H) -> 100 | Z9: =_xlfn.XLOOKUP($A9,Sheet8!$B:$B,Sheet8!I:I) -> 65 | AA9: =_xlfn.XLOOKUP($A9,Sheet8!$B:$B,Sheet8!J:J) -> 20 | AB9: =_xlfn.XLOOKUP($A9,Sheet1!$B:$B,Sheet1!G:G,0)+_xlfn.XLOOKUP($A9,Sheet2!$B:$B,Sheet2!G:G,0) -> 386 | AC9: =_xlfn.XLOOKUP($A9,Sheet3!$B:$B,Sheet3!G:G,0)+_xlfn.XLOOKUP($A9,Sheet4!$B:$B,Sheet4!G:G,0) -> 522 | AD9: =_xlfn.XLOOKUP($A9,Sheet5!$B:$B,Sheet5!G:G,0)+_xlfn.XLOOKUP($A9,Sheet6!$B:$B,Sheet6!G:G,0) -> 462 | AE9: =_xlfn.XLOOKUP($A9,Sheet7!$B:$B,Sheet7!G:G,0)+_xlfn.XLOOKUP($A9,Sheet8!$B:$B,Sheet8!G:G,0) -> 407 | AF9: {=SUM(IFERROR(AB9:AE9,0))} -> 1777 | AG9: =RANK(AF9, $AF$4:$AF$166) -> 6
A10: A011 | B10: =_xlfn.XLOOKUP($A10,Sheet3!$B:$B,Sheet3!D:D) -> 广州大学附属中学 | C10: =_xlfn.XLOOKUP($A10,Sheet3!$B:$B,Sheet3!E:E) -> 张乐涛 | D10: =_xlfn.XLOOKUP($A10,Sheet1!$B:$B,Sheet1!H:H) -> 42 | E10: =_xlfn.XLOOKUP($A10,Sheet1!$B:$B,Sheet1!I:I) -> 0 | F10: =_xlfn.XLOOKUP($A10,Sheet1!$B:$B,Sheet1!J:J) -> 18 | G10: =_xlfn.XLOOKUP($A10,Sheet2!$B:$B,Sheet2!H:H) -> 100 | H10: =_xlfn.XLOOKUP($A10,Sheet2!$B:$B,Sheet2!I:I) -> 100 | I10: =_xlfn.XLOOKUP($A10,Sheet2!$B:$B,Sheet2!J:J) -> 34 | J10: =_xlfn.XLOOKUP($A10,Sheet3!$B:$B,Sheet3!H:H) -> 100 | K10: =_xlfn.XLOOKUP($A10,Sheet3!$B:$B,Sheet3!I:I) -> 60 | L10: =_xlfn.XLOOKUP($A10,Sheet3!$B:$B,Sheet3!J:J) -> 100 | M10: =_xlfn.XLOOKUP($A10,Sheet4!$B:$B,Sheet4!H:H) -> 100 | N10: =_xlfn.XLOOKUP($A10,Sheet4!$B:$B,Sheet4!I:I) -> 100 | O10: =_xlfn.XLOOKUP($A10,Sheet4!$B:$B,Sheet4!J:J) -> 22 | P10: =_xlfn.XLOOKUP($A10,Sheet5!$B:$B,Sheet5!H:H) -> 100 | Q10: =_xlfn.XLOOKUP($A10,Sheet5!$B:$B,Sheet5!I:I) -> 32 | R10: =_xlfn.XLOOKUP($A10,Sheet5!$B:$B,Sheet5!J:J) -> 100 | S10: =_xlfn.XLOOKUP($A10,Sheet6!$B:$B,Sheet6!H:H) -> 100 | T10: =_xlfn.XLOOKUP($A10,Sheet6!$B:$B,Sheet6!I:I) -> 100 | U10: =_xlfn.XLOOKUP($A10,Sheet6!$B:$B,Sheet6!J:J) -> 100 | V10: =_xlfn.XLOOKUP($A10,Sheet7!$B:$B,Sheet7!H:H) -> 100 | W10: =_xlfn.XLOOKUP($A10,Sheet7!$B:$B,Sheet7!I:I) -> 90 | X10: =_xlfn.XLOOKUP($A10,Sheet7!$B:$B,Sheet7!J:J) -> 42 | Y10: =_xlfn.XLOOKUP($A10,Sheet8!$B:$B,Sheet8!H:H) -> 100 | Z10: =_xlfn.XLOOKUP($A10,Sheet8!$B:$B,Sheet8!I:I) -> 65 | AA10: =_xlfn.XLOOKUP($A10,Sheet8!$B:$B,Sheet8!J:J) -> 45 | AB10: =_xlfn.XLOOKUP($A10,Sheet1!$B:$B,Sheet1!G:G,0)+_xlfn.XLOOKUP($A10,Sheet2!$B:$B,Sheet2!G:G,0) -> 294 | AC10: =_xlfn.XLOOKUP($A10,Sheet3!$B:$B,Sheet3!G:G,0)+_xlfn.XLOOKUP($A10,Sheet4!$B:$B,Sheet4!G:G,0) -> 482 | AD10: =_xlfn.XLOOKUP($A10,Sheet5!$B:$B,Sheet5!G:G,0)+_xlfn.XLOOKUP($A10,Sheet6!$B:$B,Sheet6!G:G,0) -> 532 | AE10: =_xlfn.XLOOKUP($A10,Sheet7!$B:$B,Sheet7!G:G,0)+_xlfn.XLOOKUP($A10,Sheet8!$B:$B,Sheet8!G:G,0) -> 442 | AF10: {=SUM(IFERROR(AB10:AE10,0))} -> 1750 | AG10: =RANK(AF10, $AF$4:$AF$166) -> 7
A11: A031 | B11: =_xlfn.XLOOKUP($A11,Sheet3!$B:$B,Sheet3!D:D) -> 华中师范大学第一附属中学 | C11: =_xlfn.XLOOKUP($A11,Sheet3!$B:$B,Sheet3!E:E) -> 伍敬宇 | D11: =_xlfn.XLOOKUP($A11,Sheet1!$B:$B,Sheet1!H:H) -> 100 | E11: =_xlfn.XLOOKUP($A11,Sheet1!$B:$B,Sheet1!I:I) -> 42 | F11: =_xlfn.XLOOKUP($A11,Sheet1!$B:$B,Sheet1!J:J) -> 25 | G11: =_xlfn.XLOOKUP($A11,Sheet2!$B:$B,Sheet2!H:H) -> 100 | H11: =_xlfn.XLOOKUP($A11,Sheet2!$B:$B,Sheet2!I:I) -> 56 | I11: =_xlfn.XLOOKUP($A11,Sheet2!$B:$B,Sheet2!J:J) -> 34 | J11: =_xlfn.XLOOKUP($A11,Sheet3!$B:$B,Sheet3!H:H) -> 100 | K11: =_xlfn.XLOOKUP($A11,Sheet3!$B:$B,Sheet3!I:I) -> 100 | L11: =_xlfn.XLOOKUP($A11,Sheet3!$B:$B,Sheet3!J:J) -> 60 | M11: =_xlfn.XLOOKUP($A11,Sheet4!$B:$B,Sheet4!H:H) -> 100 | N11: =_xlfn.XLOOKUP($A11,Sheet4!$B:$B,Sheet4!I:I) -> 100 | O11: =_xlfn.XLOOKUP($A11,Sheet4!$B:$B,Sheet4!J:J) -> 100 | P11: =_xlfn.XLOOKUP($A11,Sheet5!$B:$B,Sheet5!H:H) -> 100 | Q11: =_xlfn.XLOOKUP($A11,Sheet5!$B:$B,Sheet5!I:I) -> 58 | R11: =_xlfn.XLOOKUP($A11,Sheet5!$B:$B,Sheet5!J:J) -> 30 | S11: =_xlfn.XLOOKUP($A11,Sheet6!$B:$B,Sheet6!H:H) -> 100 | T11: =_xlfn.XLOOKUP($A11,Sheet6!$B:$B,Sheet6!I:I) -> 100 | U11: =_xlfn.XLOOKUP($A11,Sheet6!$B:$B,Sheet6!J:J) -> 24 | V11: =_xlfn.XLOOKUP($A11,Sheet7!$B:$B,Sheet7!H:H) -> 100 | W11: =_xlfn.XLOOKUP($A11,Sheet7!$B:$B,Sheet7!I:I) -> 100 | X11: =_xlfn.XLOOKUP($A11,Sheet7!$B:$B,Sheet7!J:J) -> 85 | Y11: =_xlfn.XLOOKUP($A11,Sheet8!$B:$B,Sheet8!H:H) -> 100 | Z11: =_xlfn.XLOOKUP($A11,Sheet8!$B:$B,Sheet8!I:I) -> 0 | AA11: =_xlfn.XLOOKUP($A11,Sheet8!$B:$B,Sheet8!J:J) -> 35 | AB11: =_xlfn.XLOOKUP($A11,Sheet1!$B:$B,Sheet1!G:G,0)+_xlfn.XLOOKUP($A11,Sheet2!$B:$B,Sheet2!G:G,0) -> 357 | AC11: =_xlfn.XLOOKUP($A11,Sheet3!$B:$B,Sheet3!G:G,0)+_xlfn.XLOOKUP($A11,Sheet4!$B:$B,Sheet4!G:G,0) -> 560 | AD11: =_xlfn.XLOOKUP($A11,Sheet5!$B:$B,Sheet5!G:G,0)+_xlfn.XLOOKUP($A11,Sheet6!$B:$B,Sheet6!G:G,0) -> 412 | AE11: =_xlfn.XLOOKUP($A11,Sheet7!$B:$B,Sheet7!G:G,0)+_xlfn.XLOOKUP($A11,Sheet8!$B:$B,Sheet8!G:G,0) -> 420 | AF11: {=SUM(IFERROR(AB11:AE11,0))} -> 1749 | AG11: =RANK(AF11, $AF$4:$AF$166) -> 8
A12: A004 | B12: =_xlfn.XLOOKUP($A12,Sheet3!$B:$B,Sheet3!D:D) -> 华南师范大学附属中学 | C12: =_xlfn.XLOOKUP($A12,Sheet3!$B:$B,Sheet3!E:E) -> 叶隽霖 | D12: =_xlfn.XLOOKUP($A12,Sheet1!$B:$B,Sheet1!H:H) -> 100 | E12: =_xlfn.XLOOKUP($A12,Sheet1!$B:$B,Sheet1!I:I) -> 100 | F12: =_xlfn.XLOOKUP($A12,Sheet1!$B:$B,Sheet1!J:J) -> 25 | G12: =_xlfn.XLOOKUP($A12,Sheet2!$B:$B,Sheet2!H:H) -> 100 | H12: =_xlfn.XLOOKUP($A12,Sheet2!$B:$B,Sheet2!I:I) -> 100 | I12: =_xlfn.XLOOKUP($A12,Sheet2!$B:$B,Sheet2!J:J) -> 25 | J12: =_xlfn.XLOOKUP($A12,Sheet3!$B:$B,Sheet3!H:H) -> 100 | K12: =_xlfn.XLOOKUP($A12,Sheet3!$B:$B,Sheet3!I:I) -> 100 | L12: =_xlfn.XLOOKUP($A12,Sheet3!$B:$B,Sheet3!J:J) -> 70 | M12: =_xlfn.XLOOKUP($A12,Sheet4!$B:$B,Sheet4!H:H) -> 100 | N12: =_xlfn.XLOOKUP($A12,Sheet4!$B:$B,Sheet4!I:I) -> 100 | O12: =_xlfn.XLOOKUP($A12,Sheet4!$B:$B,Sheet4!J:J) -> 22 | P12: =_xlfn.XLOOKUP($A12,Sheet5!$B:$B,Sheet5!H:H) -> 100 | Q12: =_xlfn.XLOOKUP($A12,Sheet5!$B:$B,Sheet5!I:I) -> 100 | R12: =_xlfn.XLOOKUP($A12,Sheet5!$B:$B,Sheet5!J:J) -> 100 | S12: =_xlfn.XLOOKUP($A12,Sheet6!$B:$B,Sheet6!H:H) -> 100 | T12: =_xlfn.XLOOKUP($A12,Sheet6!$B:$B,Sheet6!I:I) -> 100 | U12: =_xlfn.XLOOKUP($A12,Sheet6!$B:$B,Sheet6!J:J) -> 100 | V12: =_xlfn.XLOOKUP($A12,Sheet7!$B:$B,Sheet7!H:H) -> 100 | W12: =_xlfn.XLOOKUP($A12,Sheet7!$B:$B,Sheet7!I:I) -> 0 | X12: =_xlfn.XLOOKUP($A12,Sheet7!$B:$B,Sheet7!J:J) -> 0 | Y12: =_xlfn.XLOOKUP($A12,Sheet8!$B:$B,Sheet8!H:H) -> 100 | Z12: =_xlfn.XLOOKUP($A12,Sheet8!$B:$B,Sheet8!I:I) -> 0 | AA12: =_xlfn.XLOOKUP($A12,Sheet8!$B:$B,Sheet8!J:J) -> 0 | AB12: =_xlfn.XLOOKUP($A12,Sheet1!$B:$B,Sheet1!G:G,0)+_xlfn.XLOOKUP($A12,Sheet2!$B:$B,Sheet2!G:G,0) -> 450 | AC12: =_xlfn.XLOOKUP($A12,Sheet3!$B:$B,Sheet3!G:G,0)+_xlfn.XLOOKUP($A12,Sheet4!$B:$B,Sheet4!G:G,0) -> 492 | AD12: =_xlfn.XLOOKUP($A12,Sheet5!$B:$B,Sheet5!G:G,0)+_xlfn.XLOOKUP($A12,Sheet6!$B:$B,Sheet6!G:G,0) -> 600 | AE12: =_xlfn.XLOOKUP($A12,Sheet7!$B:$B,Sheet7!G:G,0)+_xlfn.XLOOKUP($A12,Sheet8!$B:$B,Sheet8!G:G,0) -> 200 | AF12: {=SUM(IFERROR(AB12:AE12,0))} -> 1742 | AG12: =RANK(AF12, $AF$4:$AF$166) -> 9
A13: B005 | B13: =_xlfn.XLOOKUP($A13,Sheet3!$B:$B,Sheet3!D:D) -> 西南大学附属中学校 | C13: =_xlfn.XLOOKUP($A13,Sheet3!$B:$B,Sheet3!E:E) -> 刘恒卓 | D13: =_xlfn.XLOOKUP($A13,Sheet1!$B:$B,Sheet1!H:H) -> 100 | E13: =_xlfn.XLOOKUP($A13,Sheet1!$B:$B,Sheet1!I:I) -> 100 | F13: =_xlfn.XLOOKUP($A13,Sheet1!$B:$B,Sheet1!J:J) -> 7 | G13: =_xlfn.XLOOKUP($A13,Sheet2!$B:$B,Sheet2!H:H) -> 100 | H13: =_xlfn.XLOOKUP($A13,Sheet2!$B:$B,Sheet2!I:I) -> 56 | I13: =_xlfn.XLOOKUP($A13,Sheet2!$B:$B,Sheet2!J:J) -> 34 | J13: =_xlfn.XLOOKUP($A13,Sheet3!$B:$B,Sheet3!H:H) -> 100 | K13: =_xlfn.XLOOKUP($A13,Sheet3!$B:$B,Sheet3!I:I) -> 100 | L13: =_xlfn.XLOOKUP($A13,Sheet3!$B:$B,Sheet3!J:J) -> 80 | M13: =_xlfn.XLOOKUP($A13,Sheet4!$B:$B,Sheet4!H:H) -> 100 | N13: =_xlfn.XLOOKUP($A13,Sheet4!$B:$B,Sheet4!I:I) -> 65 | O13: =_xlfn.XLOOKUP($A13,Sheet4!$B:$B,Sheet4!J:J) -> 12 | P13: =_xlfn.XLOOKUP($A13,Sheet5!$B:$B,Sheet5!H:H) -> 100 | Q13: =_xlfn.XLOOKUP($A13,Sheet5!$B:$B,Sheet5!I:I) -> 16 | R13: =_xlfn.XLOOKUP($A13,Sheet5!$B:$B,Sheet5!J:J) -> 100 | S13: =_xlfn.XLOOKUP($A13,Sheet6!$B:$B,Sheet6!H:H) -> 100 | T13: =_xlfn.XLOOKUP($A13,Sheet6!$B:$B,Sheet6!I:I) -> 100 | U13: =_xlfn.XLOOKUP($A13,Sheet6!$B:$B,Sheet6!J:J) -> 24 | V13: =_xlfn.XLOOKUP($A13,Sheet7!$B:$B,Sheet7!H:H) -> 100 | W13: =_xlfn.XLOOKUP($A13,Sheet7!$B:$B,Sheet7!I:I) -> 90 | X13: =_xlfn.XLOOKUP($A13,Sheet7!$B:$B,Sheet7!J:J) -> 50 | Y13: =_xlfn.XLOOKUP($A13,Sheet8!$B:$B,Sheet8!H:H) -> 100 | Z13: =_xlfn.XLOOKUP($A13,Sheet8!$B:$B,Sheet8!I:I) -> 65 | AA13: =_xlfn.XLOOKUP($A13,Sheet8!$B:$B,Sheet8!J:J) -> 35 | AB13: =_xlfn.XLOOKUP($A13,Sheet1!$B:$B,Sheet1!G:G,0)+_xlfn.XLOOKUP($A13,Sheet2!$B:$B,Sheet2!G:G,0) -> 397 | AC13: =_xlfn.XLOOKUP($A13,Sheet3!$B:$B,Sheet3!G:G,0)+_xlfn.XLOOKUP($A13,Sheet4!$B:$B,Sheet4!G:G,0) -> 457 | AD13: =_xlfn.XLOOKUP($A13,Sheet5!$B:$B,Sheet5!G:G,0)+_xlfn.XLOOKUP($A13,Sheet6!$B:$B,Sheet6!G:G,0) -> 440 | AE13: =_xlfn.XLOOKUP($A13,Sheet7!$B:$B,Sheet7!G:G,0)+_xlfn.XLOOKUP($A13,Sheet8!$B:$B,Sheet8!G:G,0) -> 440 | AF13: {=SUM(IFERROR(AB13:AE13,0))} -> 1734 | AG13: =RANK(AF13, $AF$4:$AF$166) -> 10
A14: A038 | B14: =_xlfn.XLOOKUP($A14,Sheet3!$B:$B,Sheet3!D:D) -> 广州大学附属中学 | C14: =_xlfn.XLOOKUP($A14,Sheet3!$B:$B,Sheet3!E:E) -> 黄豆 | D14: =_xlfn.XLOOKUP($A14,Sheet1!$B:$B,Sheet1!H:H) -> 100 | E14: =_xlfn.XLOOKUP($A14,Sheet1!$B:$B,Sheet1!I:I) -> 42 | F14: =_xlfn.XLOOKUP($A14,Sheet1!$B:$B,Sheet1!J:J) -> 25 | G14: =_xlfn.XLOOKUP($A14,Sheet2!$B:$B,Sheet2!H:H) -> 100 | H14: =_xlfn.XLOOKUP($A14,Sheet2!$B:$B,Sheet2!I:I) -> 56 | I14: =_xlfn.XLOOKUP($A14,Sheet2!$B:$B,Sheet2!J:J) -> 58 | J14: =_xlfn.XLOOKUP($A14,Sheet3!$B:$B,Sheet3!H:H) -> 100 | K14: =_xlfn.XLOOKUP($A14,Sheet3!$B:$B,Sheet3!I:I) -> 60 | L14: =_xlfn.XLOOKUP($A14,Sheet3!$B:$B,Sheet3!J:J) -> 50 | M14: =_xlfn.XLOOKUP($A14,Sheet4!$B:$B,Sheet4!H:H) -> 100 | N14: =_xlfn.XLOOKUP($A14,Sheet4!$B:$B,Sheet4!I:I) -> 100 | O14: =_xlfn.XLOOKUP($A14,Sheet4!$B:$B,Sheet4!J:J) -> 69 | P14: =_xlfn.XLOOKUP($A14,Sheet5!$B:$B,Sheet5!H:H) -> 100 | Q14: =_xlfn.XLOOKUP($A14,Sheet5!$B:$B,Sheet5!I:I) -> 48 | R14: =_xlfn.XLOOKUP($A14,Sheet5!$B:$B,Sheet5!J:J) -> 30 | S14: =_xlfn.XLOOKUP($A14,Sheet6!$B:$B,Sheet6!H:H) -> 100 | T14: =_xlfn.XLOOKUP($A14,Sheet6!$B:$B,Sheet6!I:I) -> 100 | U14: =_xlfn.XLOOKUP($A14,Sheet6!$B:$B,Sheet6!J:J) -> 100 | V14: =_xlfn.XLOOKUP($A14,Sheet7!$B:$B,Sheet7!H:H) -> 100 | W14: =_xlfn.XLOOKUP($A14,Sheet7!$B:$B,Sheet7!I:I) -> 90 | X14: =_xlfn.XLOOKUP($A14,Sheet7!$B:$B,Sheet7!J:J) -> 10 | Y14: =_xlfn.XLOOKUP($A14,Sheet8!$B:$B,Sheet8!H:H) -> 100 | Z14: =_xlfn.XLOOKUP($A14,Sheet8!$B:$B,Sheet8!I:I) -> 65 | AA14: =_xlfn.XLOOKUP($A14,Sheet8!$B:$B,Sheet8!J:J) -> 15 | AB14: =_xlfn.XLOOKUP($A14,Sheet1!$B:$B,Sheet1!G:G,0)+_xlfn.XLOOKUP($A14,Sheet2!$B:$B,Sheet2!G:G,0) -> 381 | AC14: =_xlfn.XLOOKUP($A14,Sheet3!$B:$B,Sheet3!G:G,0)+_xlfn.XLOOKUP($A14,Sheet4!$B:$B,Sheet4!G:G,0) -> 479 | AD14: =_xlfn.XLOOKUP($A14,Sheet5!$B:$B,Sheet5!G:G,0)+_xlfn.XLOOKUP($A14,Sheet6!$B:$B,Sheet6!G:G,0) -> 478 | AE14: =_xlfn.XLOOKUP($A14,Sheet7!$B:$B,Sheet7!G:G,0)+_xlfn.XLOOKUP($A14,Sheet8!$B:$B,Sheet8!G:G,0) -> 380 | AF14: {=SUM(IFERROR(AB14:AE14,0))} -> 1718 | AG14: =RANK(AF14, $AF$4:$AF$166) -> 11
A15: A043 | B15: =_xlfn.XLOOKUP($A15,Sheet3!$B:$B,Sheet3!D:D) -> 唐山市第一中学 | C15: =_xlfn.XLOOKUP($A15,Sheet3!$B:$B,Sheet3!E:E) -> 范小冉 | D15: =_xlfn.XLOOKUP($A15,Sheet1!$B:$B,Sheet1!H:H) -> 100 | E15: =_xlfn.XLOOKUP($A15,Sheet1!$B:$B,Sheet1!I:I) -> 100 | F15: =_xlfn.XLOOKUP($A15,Sheet1!$B:$B,Sheet1!J:J) -> 18 | G15: =_xlfn.XLOOKUP($A15,Sheet2!$B:$B,Sheet2!H:H) -> 100 | H15: =_xlfn.XLOOKUP($A15,Sheet2!$B:$B,Sheet2!I:I) -> 0 | I15: =_xlfn.XLOOKUP($A15,Sheet2!$B:$B,Sheet2!J:J) -> 34 | J15: =_xlfn.XLOOKUP($A15,Sheet3!$B:$B,Sheet3!H:H) -> 84 | K15: =_xlfn.XLOOKUP($A15,Sheet3!$B:$B,Sheet3!I:I) -> 100 | L15: =_xlfn.XLOOKUP($A15,Sheet3!$B:$B,Sheet3!J:J) -> 40 | M15: =_xlfn.XLOOKUP($A15,Sheet4!$B:$B,Sheet4!H:H) -> 100 | N15: =_xlfn.XLOOKUP($A15,Sheet4!$B:$B,Sheet4!I:I) -> 11 | O15: =_xlfn.XLOOKUP($A15,Sheet4!$B:$B,Sheet4!J:J) -> 100 | P15: =_xlfn.XLOOKUP($A15,Sheet5!$B:$B,Sheet5!H:H) -> 100 | Q15: =_xlfn.XLOOKUP($A15,Sheet5!$B:$B,Sheet5!I:I) -> 74 | R15: =_xlfn.XLOOKUP($A15,Sheet5!$B:$B,Sheet5!J:J) -> 30 | S15: =_xlfn.XLOOKUP($A15,Sheet6!$B:$B,Sheet6!H:H) -> 100 | T15: =_xlfn.XLOOKUP($A15,Sheet6!$B:$B,Sheet6!I:I) -> 100 | U15: =_xlfn.XLOOKUP($A15,Sheet6!$B:$B,Sheet6!J:J) -> 100 | V15: =_xlfn.XLOOKUP($A15,Sheet7!$B:$B,Sheet7!H:H) -> 0 | W15: =_xlfn.XLOOKUP($A15,Sheet7!$B:$B,Sheet7!I:I) -> 90 | X15: =_xlfn.XLOOKUP($A15,Sheet7!$B:$B,Sheet7!J:J) -> 100 | Y15: =_xlfn.XLOOKUP($A15,Sheet8!$B:$B,Sheet8!H:H) -> 100 | Z15: =_xlfn.XLOOKUP($A15,Sheet8!$B:$B,Sheet8!I:I) -> 100 | AA15: =_xlfn.XLOOKUP($A15,Sheet8!$B:$B,Sheet8!J:J) -> 0 | AB15: =_xlfn.XLOOKUP($A15,Sheet1!$B:$B,Sheet1!G:G,0)+_xlfn.XLOOKUP($A15,Sheet2!$B:$B,Sheet2!G:G,0) -> 352 | AC15: =_xlfn.XLOOKUP($A15,Sheet3!$B:$B,Sheet3!G:G,0)+_xlfn.XLOOKUP($A15,Sheet4!$B:$B,Sheet4!G:G,0) -> 435 | AD15: =_xlfn.XLOOKUP($A15,Sheet5!$B:$B,Sheet5!G:G,0)+_xlfn.XLOOKUP($A15,Sheet6!$B:$B,Sheet6!G:G,0) -> 504 | AE15: =_xlfn.XLOOKUP($A15,Sheet7!$B:$B,Sheet7!G:G,0)+_xlfn.XLOOKUP($A15,Sheet8!$B:$B,Sheet8!G:G,0) -> 390 | AF15: {=SUM(IFERROR(AB15:AE15,0))} -> 1681 | AG15: =RANK(AF15, $AF$4:$AF$166) -> 12
... A165: D028 | B165: =_xlfn.XLOOKUP($A165,Sheet3!$B:$B,Sheet3!D:D) -> 中山市中山纪念中学 | C165: =_xlfn.XLOOKUP($A165,Sheet3!$B:$B,Sheet3!E:E) -> 王逸文 | D165: =_xlfn.XLOOKUP($A165,Sheet1!$B:$B,Sheet1!H:H) -> 0 | E165: =_xlfn.XLOOKUP($A165,Sheet1!$B:$B,Sheet1!I:I) -> 0 | F165: =_xlfn.XLOOKUP($A165,Sheet1!$B:$B,Sheet1!J:J) -> 0 | G165: =_xlfn.XLOOKUP($A165,Sheet2!$B:$B,Sheet2!H:H) -> 0 | H165: =_xlfn.XLOOKUP($A165,Sheet2!$B:$B,Sheet2!I:I) -> 0 | I165: =_xlfn.XLOOKUP($A165,Sheet2!$B:$B,Sheet2!J:J) -> 12 | J165: =_xlfn.XLOOKUP($A165,Sheet3!$B:$B,Sheet3!H:H) -> 48 | K165: =_xlfn.XLOOKUP($A165,Sheet3!$B:$B,Sheet3!I:I) -> 40 | L165: =_xlfn.XLOOKUP($A165,Sheet3!$B:$B,Sheet3!J:J) -> 0 | M165: =_xlfn.XLOOKUP($A165,Sheet4!$B:$B,Sheet4!H:H) -> 10 | N165: =_xlfn.XLOOKUP($A165,Sheet4!$B:$B,Sheet4!I:I) -> 0 | O165: =_xlfn.XLOOKUP($A165,Sheet4!$B:$B,Sheet4!J:J) -> 1 | P165: =_xlfn.XLOOKUP($A165,Sheet5!$B:$B,Sheet5!H:H) -> 55 | Q165: =_xlfn.XLOOKUP($A165,Sheet5!$B:$B,Sheet5!I:I) -> 0 | R165: =_xlfn.XLOOKUP($A165,Sheet5!$B:$B,Sheet5!J:J) -> 0 | S165: =_xlfn.XLOOKUP($A165,Sheet6!$B:$B,Sheet6!H:H) -> 20 | T165: =_xlfn.XLOOKUP($A165,Sheet6!$B:$B,Sheet6!I:I) -> 36 | U165: =_xlfn.XLOOKUP($A165,Sheet6!$B:$B,Sheet6!J:J) -> 8 | V165: =_xlfn.XLOOKUP($A165,Sheet7!$B:$B,Sheet7!H:H) -> 15 | W165: =_xlfn.XLOOKUP($A165,Sheet7!$B:$B,Sheet7!I:I) -> 10 | X165: =_xlfn.XLOOKUP($A165,Sheet7!$B:$B,Sheet7!J:J) -> 0 | Y165: =_xlfn.XLOOKUP($A165,Sheet8!$B:$B,Sheet8!H:H) -> 0 | Z165: =_xlfn.XLOOKUP($A165,Sheet8!$B:$B,Sheet8!I:I) -> 0 | AA165: =_xlfn.XLOOKUP($A165,Sheet8!$B:$B,Sheet8!J:J) -> 0 | AB165: =_xlfn.XLOOKUP($A165,Sheet1!$B:$B,Sheet1!G:G,0)+_xlfn.XLOOKUP($A165,Sheet2!$B:$B,Sheet2!G:G,0) -> 12 | AC165: =_xlfn.XLOOKUP($A165,Sheet3!$B:$B,Sheet3!G:G,0)+_xlfn.XLOOKUP($A165,Sheet4!$B:$B,Sheet4!G:G,0) -> 99 | AD165: =_xlfn.XLOOKUP($A165,Sheet5!$B:$B,Sheet5!G:G,0)+_xlfn.XLOOKUP($A165,Sheet6!$B:$B,Sheet6!G:G,0) -> 119 | AE165: =_xlfn.XLOOKUP($A165,Sheet7!$B:$B,Sheet7!G:G,0)+_xlfn.XLOOKUP($A165,Sheet8!$B:$B,Sheet8!G:G,0) -> 25 | AF165: {=SUM(IFERROR(AB165:AE165,0))} -> 255 | AG165: =RANK(AF165, $AF$4:$AF$166) -> 162
